Workbook

Sheet Navigation
B2: TRELLIS CLIMATE - PRIME COALITION
B4: Climate Tech - Bridge Rounds Research
B5: Phase 1
B8: How to use this model This workbook is structured to move from raw deal-level data to cleaned and standardized data to analytical outputs and charts. The Raw Data tab contains the full set of bridge and extension rounds pulled from source databases. The Sanitized Data tab applies consistent formatting, standardized company names, dates, subsectors, and deal attributes, and is the primary input for all analysis. The Outputs tab aggregates this data into key metrics such as repeat investors, deal size distributions, capital deployed over time, and debt usage. Charts and visuals are generated from the Analytics tab and should not be edited directly. If you plan to update the dataset, start with modifying the Raw Data tab. All downstream tabs should only be updated update regarding the string of rows used as input. The Exclusions & Distinctions tab includes two lists of companies that were reviewed manually to determine inclusion in the dataset. The tabs with the identifier "Setup" are used to avoid embedding complex formulas in the analysis tabs and can be ignored.

Sheet Outputs
B2: KEY METRICS
B5: Deal size (USD MM)
C6: Overall | D6: Renewables | E6: LDES | F6: Hydrogen | G6: CDR | H6: Industrial Decarbonization | I6: Buildings | J6: Mobility | K6: Food&Ag
B7: Minimum | C7: =_xlfn.MINIFS(Cleaned_Data!$J$3:$J$273,Cleaned_Data!$J$3:$J$273, ">0") -> 0.02 | D7: =_xlfn.MINIFS(Cleaned_Data!$J$3:$J$273,Cleaned_Data!$F$3:$F$273, "Renewables", Cleaned_Data!$J$3:$J$273, ">0") -> 0.25 | E7: =_xlfn.MINIFS(Cleaned_Data!$J$3:$J$273,Cleaned_Data!$F$3:$F$273, "LDES", Cleaned_Data!$J$3:$J$273, ">0") -> 0.08 | F7: =_xlfn.MINIFS(Cleaned_Data!$J$3:$J$273,Cleaned_Data!$F$3:$F$273, "Hydrogen", Cleaned_Data!$J$3:$J$273, ">0") -> 0.18 | G7: =_xlfn.MINIFS(Cleaned_Data!$J$3:$J$273,Cleaned_Data!$F$3:$F$273, "CDR", Cleaned_Data!$J$3:$J$273, ">0") -> 0.13 | H7: =_xlfn.MINIFS(Cleaned_Data!$J$3:$J$273,Cleaned_Data!$F$3:$F$273, "Industrial Decarbonization", Cleaned_Data!$J$3:$J$273, ">0") -> 0.1 | I7: =_xlfn.MINIFS(Cleaned_Data!$J$3:$J$273,Cleaned_Data!$F$3:$F$273, "Buildings", Cleaned_Data!$J$3:$J$273, ">0") -> 0.57 | J7: =_xlfn.MINIFS(Cleaned_Data!$J$3:$J$273,Cleaned_Data!$F$3:$F$273, "Mobility", Cleaned_Data!$J$3:$J$273, ">0") -> 0.1 | K7: =_xlfn.MINIFS(Cleaned_Data!$J$3:$J$273,Cleaned_Data!$F$3:$F$273, "Food & Ag", Cleaned_Data!$J$3:$J$273, ">0") -> 0.02
B8: Median | C8: =MEDIAN(_xlfn._xlws.FILTER(Cleaned_Data!$J$3:$J$273,Cleaned_Data!$J$3:$J$273, ">0")) -> 9.89 | D8: {=MEDIAN(_xlfn._xlws.FILTER(Cleaned_Data!$J$3:$J$273,(Cleaned_Data!$F$3:$F$273="Renewables")*(Cleaned_Data!$J$3:$J$273>0)))} -> 13 | E8: {=MEDIAN(_xlfn._xlws.FILTER(Cleaned_Data!$J$3:$J$273,(Cleaned_Data!$F$3:$F$273="LDES")*(Cleaned_Data!$J$3:$J$273>0)))} -> 6.5 | F8: {=MEDIAN(_xlfn._xlws.FILTER(Cleaned_Data!$J$3:$J$273,(Cleaned_Data!$F$3:$F$273="Hydrogen")*(Cleaned_Data!$J$3:$J$273>0)))} -> 12.5 | G8: {=MEDIAN(_xlfn._xlws.FILTER(Cleaned_Data!$J$3:$J$273,(Cleaned_Data!$F$3:$F$273="CDR")*(Cleaned_Data!$J$3:$J$273>0)))} -> 39 | H8: {=MEDIAN(_xlfn._xlws.FILTER(Cleaned_Data!$J$3:$J$273,(Cleaned_Data!$F$3:$F$273="Industrial Decarbonization")*(Cleaned_Data!$J$3:$J$273>0)))} -> 6.7 | I8: {=MEDIAN(_xlfn._xlws.FILTER(Cleaned_Data!$J$3:$J$273,(Cleaned_Data!$F$3:$F$273="Buildings")*(Cleaned_Data!$J$3:$J$273>0)))} -> 7.75 | J8: {=MEDIAN(_xlfn._xlws.FILTER(Cleaned_Data!$J$3:$J$273,(Cleaned_Data!$F$3:$F$273="Mobility")*(Cleaned_Data!$J$3:$J$273>0)))} -> 8.975 | K8: {=MEDIAN(_xlfn._xlws.FILTER(Cleaned_Data!$J$3:$J$273,(Cleaned_Data!$F$3:$F$273="Food & Ag")*(Cleaned_Data!$J$3:$J$273>0)))} -> 8
B9: Average | C9: =AVERAGEIFS(Cleaned_Data!$J$3:$J$273,Cleaned_Data!$J$3:$J$273, ">0") -> 46.603982 | D9: =AVERAGEIFS(Cleaned_Data!$J$3:$J$273,Cleaned_Data!$F$3:$F$273, "Renewables", Cleaned_Data!$J$3:$J$273, ">0") -> 88.747333 | E9: =AVERAGEIFS(Cleaned_Data!$J$3:$J$273,Cleaned_Data!$F$3:$F$273, "LDES", Cleaned_Data!$J$3:$J$273, ">0") -> 19.469 | F9: =AVERAGEIFS(Cleaned_Data!$J$3:$J$273,Cleaned_Data!$F$3:$F$273, "Hydrogen", Cleaned_Data!$J$3:$J$273, ">0") -> 51.111923 | G9: =AVERAGEIFS(Cleaned_Data!$J$3:$J$273,Cleaned_Data!$F$3:$F$273, "CDR", Cleaned_Data!$J$3:$J$273, ">0") -> 51.5025 | H9: =AVERAGEIFS(Cleaned_Data!$J$3:$J$273,Cleaned_Data!$F$3:$F$273, "Industrial Decarbonization", Cleaned_Data!$J$3:$J$273, ">0") -> 26.962093 | I9: =AVERAGEIFS(Cleaned_Data!$J$3:$J$273,Cleaned_Data!$F$3:$F$273, "Buildings", Cleaned_Data!$J$3:$J$273, ">0") -> 12.103333 | J9: =AVERAGEIFS(Cleaned_Data!$J$3:$J$273,Cleaned_Data!$F$3:$F$273, "Mobility", Cleaned_Data!$J$3:$J$273, ">0") -> 81.479 | K9: =AVERAGEIFS(Cleaned_Data!$J$3:$J$273,Cleaned_Data!$F$3:$F$273, "Food & Ag", Cleaned_Data!$J$3:$J$273, ">0") -> 26.019459
B10: Maximum | C10: =_xlfn.MAXIFS(Cleaned_Data!$J$3:$J$273,Cleaned_Data!$J$3:$J$273, ">0") -> 1250 | D10: =_xlfn.MAXIFS(Cleaned_Data!$J$3:$J$273,Cleaned_Data!$F$3:$F$273, "Renewables", Cleaned_Data!$J$3:$J$273, ">0") -> 863 | E10: =_xlfn.MAXIFS(Cleaned_Data!$J$3:$J$273,Cleaned_Data!$F$3:$F$273, "LDES", Cleaned_Data!$J$3:$J$273, ">0") -> 120 | F10: =_xlfn.MAXIFS(Cleaned_Data!$J$3:$J$273,Cleaned_Data!$F$3:$F$273, "Hydrogen", Cleaned_Data!$J$3:$J$273, ">0") -> 650 | G10: =_xlfn.MAXIFS(Cleaned_Data!$J$3:$J$273,Cleaned_Data!$F$3:$F$273, "CDR", Cleaned_Data!$J$3:$J$273, ">0") -> 160 | H10: =_xlfn.MAXIFS(Cleaned_Data!$J$3:$J$273,Cleaned_Data!$F$3:$F$273, "Industrial Decarbonization", Cleaned_Data!$J$3:$J$273, ">0") -> 250 | I10: =_xlfn.MAXIFS(Cleaned_Data!$J$3:$J$273,Cleaned_Data!$F$3:$F$273, "Buildings", Cleaned_Data!$J$3:$J$273, ">0") -> 69.7 | J10: =_xlfn.MAXIFS(Cleaned_Data!$J$3:$J$273,Cleaned_Data!$F$3:$F$273, "Mobility", Cleaned_Data!$J$3:$J$273, ">0") -> 1250 | K10: =_xlfn.MAXIFS(Cleaned_Data!$J$3:$J$273,Cleaned_Data!$F$3:$F$273, "Food & Ag", Cleaned_Data!$J$3:$J$273, ">0") -> 300
B13: Deal Stage Analysis
C14: Overall | D14: Renewables | E14: LDES | F14: Hydrogen | G14: CDR | H14: Industrial Decarbonization | I14: Buildings | J14: Mobility | K14: Food&Ag
B15: Most Common Stage | C15: {=_xlfn.LET(_xlpm.stages, _xlfn._xlws.FILTER(Cleaned_Data!$H$3:$H$273, Cleaned_Data!$H$3:$H$273<>""),INDEX(_xlpm.stages,MODE(MATCH(_xlpm.stages, _xlpm.stages, 0))))} -> Series A | D15: {=_xlfn.LET(_xlpm.stages,_xlfn._xlws.FILTER(Cleaned_Data!$H$3:$H$273,(Cleaned_Data!$F$3:$F$273="Renewables")*(Cleaned_Data!$H$3:$H$273<>"")),INDEX(_xlpm.stages,MODE(MATCH(_xlpm.stages, _xlpm.stages, 0))))} -> Development capital | E15: {=_xlfn.LET(_xlpm.stages,_xlfn._xlws.FILTER(Cleaned_Data!$H$3:$H$273,(Cleaned_Data!$F$3:$F$273="LDES")*(Cleaned_Data!$H$3:$H$273<>"")),INDEX(_xlpm.stages,MODE(MATCH(_xlpm.stages, _xlpm.stages, 0))))} -> Series A | F15: {=_xlfn.LET(_xlpm.stages,_xlfn._xlws.FILTER(Cleaned_Data!$H$3:$H$273,(Cleaned_Data!$F$3:$F$273="Hydrogen")*(Cleaned_Data!$H$3:$H$273<>"")),INDEX(_xlpm.stages,MODE(MATCH(_xlpm.stages, _xlpm.stages, 0))))} -> Development capital | G15: {=_xlfn.LET(_xlpm.stages,_xlfn._xlws.FILTER(Cleaned_Data!$H$3:$H$273,(Cleaned_Data!$F$3:$F$273="CDR")*(Cleaned_Data!$H$3:$H$273<>"")),INDEX(_xlpm.stages,MODE(MATCH(_xlpm.stages, _xlpm.stages, 0))))} -> Development capital | H15: {=_xlfn.LET(_xlpm.stages,_xlfn._xlws.FILTER(Cleaned_Data!$H$3:$H$273,(Cleaned_Data!$F$3:$F$273="Industrial Decarbonization")*(Cleaned_Data!$H$3:$H$273<>"")),INDEX(_xlpm.stages,MODE(MATCH(_xlpm.stages, _xlpm.stages, 0))))} -> Series A | I15: {=_xlfn.LET(_xlpm.stages,_xlfn._xlws.FILTER(Cleaned_Data!$H$3:$H$273,(Cleaned_Data!$F$3:$F$273="Buildings")*(Cleaned_Data!$H$3:$H$273<>"")),INDEX(_xlpm.stages,MODE(MATCH(_xlpm.stages, _xlpm.stages, 0))))} -> Series A | J15: {=_xlfn.LET(_xlpm.stages,_xlfn._xlws.FILTER(Cleaned_Data!$H$3:$H$273,(Cleaned_Data!$F$3:$F$273="Mobility")*(Cleaned_Data!$H$3:$H$273<>"")),INDEX(_xlpm.stages,MODE(MATCH(_xlpm.stages, _xlpm.stages, 0))))} -> Development capital | K15: {=_xlfn.LET(_xlpm.stages,_xlfn._xlws.FILTER(Cleaned_Data!$H$3:$H$273,(Cleaned_Data!$F$3:$F$273="Food & Ag")*(Cleaned_Data!$H$3:$H$273<>"")),INDEX(_xlpm.stages,MODE(MATCH(_xlpm.stages, _xlpm.stages, 0))))} -> Series A
C17: Overall | D17: Seed | E17: Series A | F17: Series B | G17: Development Capital
B18: Total # of rounds | C18: =COUNTIF(Cleaned_Data!$H$3:$H$273, "<>") -> 254 | D18: =COUNTIF(Cleaned_Data!$H$3:$H$273, "Seed") -> 43 | E18: =COUNTIF(Cleaned_Data!$H$3:$H$273, "Series A") -> 81 | F18: =COUNTIF(Cleaned_Data!$H$3:$H$273, "Series B") -> 42 | G18: =COUNTIF(Cleaned_Data!$H$3:$H$273, "Development Capital") -> 80
B19: Median Size | C19: {=MEDIAN(_xlfn._xlws.FILTER(Cleaned_Data!$J$3:$J$273,Cleaned_Data!$J$3:$J$273>0))} -> 9.89 | D19: {=MEDIAN(_xlfn._xlws.FILTER(Cleaned_Data!$J$3:$J$273,(Cleaned_Data!$H$3:$H$273="Seed")*(Cleaned_Data!$J$3:$J$273>0)))} -> 1.805 | E19: {=MEDIAN(_xlfn._xlws.FILTER(Cleaned_Data!$J$3:$J$273,(Cleaned_Data!$H$3:$H$273="Series A")*(Cleaned_Data!$J$3:$J$273>0)))} -> 9.89 | F19: {=MEDIAN(_xlfn._xlws.FILTER(Cleaned_Data!$J$3:$J$273,(Cleaned_Data!$H$3:$H$273="Series B")*(Cleaned_Data!$J$3:$J$273>0)))} -> 18.345 | G19: {=MEDIAN(_xlfn._xlws.FILTER(Cleaned_Data!$J$3:$J$273,(Cleaned_Data!$H$3:$H$273="Development Capital")*(Cleaned_Data!$J$3:$J$273>0)))} -> 30
B22: Time Series Analysis
C23: 2015 | D23: =C23+1 -> 2016 | E23: =D23+1 -> 2017 | F23: =E23+1 -> 2018 | G23: =F23+1 -> 2019 | H23: =G23+1 -> 2020 | I23: =H23+1 -> 2021 | J23: =I23+1 -> 2022 | K23: =J23+1 -> 2023 | ... M23: =L23+1 -> 2025
B24: Total Capital Invested | C24: =SUMIFS( Cleaned_Data!$J$3:$J$273,Cleaned_Data!$G$3:$G$273, ">="&DATE(C$23,1,1), Cleaned_Data!$G$3:$G$273, "<"&DATE(C$23+1,1,1), Cleaned_Data!$J$3:$J$273, ">0") -> 370.54 | D24: =SUMIFS( Cleaned_Data!$J$3:$J$273,Cleaned_Data!$G$3:$G$273, ">="&DATE(D$23,1,1), Cleaned_Data!$G$3:$G$273, "<"&DATE(D$23+1,1,1), Cleaned_Data!$J$3:$J$273, ">0") -> 295.5 | E24: =SUMIFS( Cleaned_Data!$J$3:$J$273,Cleaned_Data!$G$3:$G$273, ">="&DATE(E$23,1,1), Cleaned_Data!$G$3:$G$273, "<"&DATE(E$23+1,1,1), Cleaned_Data!$J$3:$J$273, ">0") -> 44.32 | F24: =SUMIFS( Cleaned_Data!$J$3:$J$273,Cleaned_Data!$G$3:$G$273, ">="&DATE(F$23,1,1), Cleaned_Data!$G$3:$G$273, "<"&DATE(F$23+1,1,1), Cleaned_Data!$J$3:$J$273, ">0") -> 103.31 | G24: =SUMIFS( Cleaned_Data!$J$3:$J$273,Cleaned_Data!$G$3:$G$273, ">="&DATE(G$23,1,1), Cleaned_Data!$G$3:$G$273, "<"&DATE(G$23+1,1,1), Cleaned_Data!$J$3:$J$273, ">0") -> 1631.59 | H24: =SUMIFS( Cleaned_Data!$J$3:$J$273,Cleaned_Data!$G$3:$G$273, ">="&DATE(H$23,1,1), Cleaned_Data!$G$3:$G$273, "<"&DATE(H$23+1,1,1), Cleaned_Data!$J$3:$J$273, ">0") -> 1007.94 | I24: =SUMIFS( Cleaned_Data!$J$3:$J$273,Cleaned_Data!$G$3:$G$273, ">="&DATE(I$23,1,1), Cleaned_Data!$G$3:$G$273, "<"&DATE(I$23+1,1,1), Cleaned_Data!$J$3:$J$273, ">0") -> 475.25 | J24: =SUMIFS( Cleaned_Data!$J$3:$J$273,Cleaned_Data!$G$3:$G$273, ">="&DATE(J$23,1,1), Cleaned_Data!$G$3:$G$273, "<"&DATE(J$23+1,1,1), Cleaned_Data!$J$3:$J$273, ">0") -> 2796.84 | ... M24: =SUMIFS( Cleaned_Data!$J$3:$J$273,Cleaned_Data!$G$3:$G$273, ">="&DATE(M$23,1,1), Cleaned_Data!$G$3:$G$273, "<"&DATE(M$23+1,1,1), Cleaned_Data!$J$3:$J$273, ">0") -> 1905.92
B25: Deal Count | C25: =COUNTIFS(Cleaned_Data!$G$3:$G$273, ">=1/1/2015", Cleaned_Data!$G$3:$G$273, "<1/1/2016") -> 5 | D25: =COUNTIFS(Cleaned_Data!$G$3:$G$273, ">=1/1/2016", Cleaned_Data!$G$3:$G$273, "<1/1/2017") -> 10 | E25: =COUNTIFS(Cleaned_Data!$G$3:$G$273, ">=1/1/2017", Cleaned_Data!$G$3:$G$273, "<1/1/2018") -> 9 | F25: =COUNTIFS(Cleaned_Data!$G$3:$G$273, ">=1/1/2018", Cleaned_Data!$G$3:$G$273, "<1/1/2019") -> 13 | G25: =COUNTIFS(Cleaned_Data!$G$3:$G$273, ">=1/1/2019", Cleaned_Data!$G$3:$G$273, "<1/1/2020") -> 16 | H25: =COUNTIFS(Cleaned_Data!$G$3:$G$273, ">=1/1/2020", Cleaned_Data!$G$3:$G$273, "<1/1/2021") -> 22 | I25: =COUNTIFS(Cleaned_Data!$G$3:$G$273, ">=1/1/2021", Cleaned_Data!$G$3:$G$273, "<1/1/2022") -> 47 | J25: =COUNTIFS(Cleaned_Data!$G$3:$G$273, ">=1/1/2022", Cleaned_Data!$G$3:$G$273, "<1/1/2023") -> 45 | K25: =COUNTIFS(Cleaned_Data!$G$3:$G$273, ">=1/1/2023", Cleaned_Data!$G$3:$G$273, "<1/1/2024") -> 39 | L25: =COUNTIFS(Cleaned_Data!$G$3:$G$273, ">=1/1/2024", Cleaned_Data!$G$3:$G$273, "<1/1/2025") -> 35 | M25: =COUNTIFS(Cleaned_Data!$G$3:$G$273, ">=1/1/2025", Cleaned_Data!$G$3:$G$273, "<1/1/2026") -> 29
B26: Median Deal Size | C26: {=MEDIAN( _xlfn._xlws.FILTER( Cleaned_Data!$J$3:$J$273, (Cleaned_Data!$G$3:$G$273>=DATE(2015,1,1))* (Cleaned_Data!$G$3:$G$273<DATE(2016,1,1))* (Cleaned_Data!$J$3:$J$273>0)))} -> 11 | D26: {=MEDIAN( _xlfn._xlws.FILTER( Cleaned_Data!$J$3:$J$273, (Cleaned_Data!$G$3:$G$273>=DATE(2016,1,1))* (Cleaned_Data!$G$3:$G$273<DATE(2017,1,1))* (Cleaned_Data!$J$3:$J$273>0)))} -> 4.92 | E26: {=MEDIAN( _xlfn._xlws.FILTER( Cleaned_Data!$J$3:$J$273, (Cleaned_Data!$G$3:$G$273>=DATE(2017,1,1))* (Cleaned_Data!$G$3:$G$273<DATE(2018,1,1))* (Cleaned_Data!$J$3:$J$273>0)))} -> 3.92 | F26: {=MEDIAN( _xlfn._xlws.FILTER( Cleaned_Data!$J$3:$J$273, (Cleaned_Data!$G$3:$G$273>=DATE(2018,1,1))* (Cleaned_Data!$G$3:$G$273<DATE(2019,1,1))* (Cleaned_Data!$J$3:$J$273>0)))} -> 5.25 | G26: {=MEDIAN( _xlfn._xlws.FILTER( Cleaned_Data!$J$3:$J$273, (Cleaned_Data!$G$3:$G$273>=DATE(2019,1,1))* (Cleaned_Data!$G$3:$G$273<DATE(2020,1,1))* (Cleaned_Data!$J$3:$J$273>0)))} -> 6.51 | H26: {=MEDIAN( _xlfn._xlws.FILTER( Cleaned_Data!$J$3:$J$273, (Cleaned_Data!$G$3:$G$273>=DATE(2020,1,1))* (Cleaned_Data!$G$3:$G$273<DATE(2021,1,1))* (Cleaned_Data!$J$3:$J$273>0)))} -> 12 | I26: {=MEDIAN( _xlfn._xlws.FILTER( Cleaned_Data!$J$3:$J$273, (Cleaned_Data!$G$3:$G$273>=DATE(2021,1,1))* (Cleaned_Data!$G$3:$G$273<DATE(2022,1,1))* (Cleaned_Data!$J$3:$J$273>0)))} -> 7 | J26: {=MEDIAN( _xlfn._xlws.FILTER( Cleaned_Data!$J$3:$J$273, (Cleaned_Data!$G$3:$G$273>=DATE(2022,1,1))* (Cleaned_Data!$G$3:$G$273<DATE(2023,1,1))* (Cleaned_Data!$J$3:$J$273>0)))} -> 5.125 | K26: {=MEDIAN( _xlfn._xlws.FILTER( Cleaned_Data!$J$3:$J$273, (Cleaned_Data!$G$3:$G$273>=DATE(2023,1,1))* (Cleaned_Data!$G$3:$G$273<DATE(2024,1,1))* (Cleaned_Data!$J$3:$J$273>0)))} -> 12 | L26: {=MEDIAN( _xlfn._xlws.FILTER( Cleaned_Data!$J$3:$J$273, (Cleaned_Data!$G$3:$G$273>=DATE(2024,1,1))* (Cleaned_Data!$G$3:$G$273<DATE(2025,1,1))* (Cleaned_Data!$J$3:$J$273>0)))} -> 15 | M26: {=MEDIAN( _xlfn._xlws.FILTER( Cleaned_Data!$J$3:$J$273, (Cleaned_Data!$G$3:$G$273>=DATE(2025,1,1))* (Cleaned_Data!$G$3:$G$273<DATE(2026,1,1))* (Cleaned_Data!$J$3:$J$273>0)))} -> 25.13
B27: Median Valuation | C27: {=MEDIAN(_xlfn._xlws.FILTER(Cleaned_Data!$K$3:$K$273, (Cleaned_Data!$G$3:$G$273>=DATE(2015,1,1))* (Cleaned_Data!$G$3:$G$273<DATE(2016,1,1))* (Cleaned_Data!$K$3:$K$273>0)))} -> 35.605 | D27: {=MEDIAN( _xlfn._xlws.FILTER( Cleaned_Data!$K$3:$K$273, (Cleaned_Data!$G$3:$G$273>=DATE(2016,1,1))* (Cleaned_Data!$G$3:$G$273<DATE(2017,1,1))* (Cleaned_Data!$K$3:$K$273>0)))} -> 19.45 | E27: {=MEDIAN( _xlfn._xlws.FILTER( Cleaned_Data!$K$3:$K$273, (Cleaned_Data!$G$3:$G$273>=DATE(2017,1,1))* (Cleaned_Data!$G$3:$G$273<DATE(2018,1,1))* (Cleaned_Data!$K$3:$K$273>0)))} -> 19 | F27: {=MEDIAN( _xlfn._xlws.FILTER( Cleaned_Data!$K$3:$K$273, (Cleaned_Data!$G$3:$G$273>=DATE(2018,1,1))* (Cleaned_Data!$G$3:$G$273<DATE(2019,1,1))* (Cleaned_Data!$K$3:$K$273>0)))} -> 30 | G27: {=MEDIAN( _xlfn._xlws.FILTER( Cleaned_Data!$K$3:$K$273, (Cleaned_Data!$G$3:$G$273>=DATE(2019,1,1))* (Cleaned_Data!$G$3:$G$273<DATE(2020,1,1))* (Cleaned_Data!$K$3:$K$273>0)))} -> 21.5 | H27: {=MEDIAN( _xlfn._xlws.FILTER( Cleaned_Data!$K$3:$K$273, (Cleaned_Data!$G$3:$G$273>=DATE(2020,1,1))* (Cleaned_Data!$G$3:$G$273<DATE(2021,1,1))* (Cleaned_Data!$K$3:$K$273>0)))} -> 35.065 | I27: {=MEDIAN( _xlfn._xlws.FILTER( Cleaned_Data!$K$3:$K$273, (Cleaned_Data!$G$3:$G$273>=DATE(2021,1,1))* (Cleaned_Data!$G$3:$G$273<DATE(2022,1,1))* (Cleaned_Data!$K$3:$K$273>0)))} -> 20.95 | J27: {=MEDIAN( _xlfn._xlws.FILTER( Cleaned_Data!$K$3:$K$273, (Cleaned_Data!$G$3:$G$273>=DATE(2022,1,1))* (Cleaned_Data!$G$3:$G$273<DATE(2023,1,1))* (Cleaned_Data!$K$3:$K$273>0)))} -> 38.325 | K27: {=MEDIAN( _xlfn._xlws.FILTER( Cleaned_Data!$K$3:$K$273, (Cleaned_Data!$G$3:$G$273>=DATE(2023,1,1))* (Cleaned_Data!$G$3:$G$273<DATE(2024,1,1))* (Cleaned_Data!$K$3:$K$273>0)))} -> 83 | L27: {=MEDIAN( _xlfn._xlws.FILTER( Cleaned_Data!$K$3:$K$273, (Cleaned_Data!$G$3:$G$273>=DATE(2024,1,1))* (Cleaned_Data!$G$3:$G$273<DATE(2025,1,1))* (Cleaned_Data!$K$3:$K$273>0)))} -> 70.6 | M27: {=MEDIAN( _xlfn._xlws.FILTER( Cleaned_Data!$K$3:$K$273, (Cleaned_Data!$G$3:$G$273>=DATE(2025,1,1))* (Cleaned_Data!$G$3:$G$273<DATE(2026,1,1))* (Cleaned_Data!$K$3:$K$273>0)))} -> 200
B28: Deal Stage | C28: {=_xlfn.LET( _xlpm.stages, _xlfn._xlws.FILTER( Cleaned_Data!$H$3:$H$273, (Cleaned_Data!$G$3:$G$273>=DATE(2015,1,1))* (Cleaned_Data!$G$3:$G$273<DATE(2016,1,1))* (Cleaned_Data!$H$3:$H$273<>"")), INDEX( _xlpm.stages, MODE( MATCH(_xlpm.stages, _xlpm.stages, 0))))} -> Development capital | D28: {=_xlfn.LET( _xlpm.stages, _xlfn._xlws.FILTER( Cleaned_Data!$H$3:$H$273, (Cleaned_Data!$G$3:$G$273>=DATE(2016,1,1))* (Cleaned_Data!$G$3:$G$273<DATE(2017,1,1))* (Cleaned_Data!$H$3:$H$273<>"")), INDEX( _xlpm.stages, MODE( MATCH(_xlpm.stages, _xlpm.stages, 0))))} -> Series A | E28: {=_xlfn.LET( _xlpm.stages, _xlfn._xlws.FILTER( Cleaned_Data!$H$3:$H$273, (Cleaned_Data!$G$3:$G$273>=DATE(2017,1,1))* (Cleaned_Data!$G$3:$G$273<DATE(2018,1,1))* (Cleaned_Data!$H$3:$H$273<>"")), INDEX( _xlpm.stages, MODE( MATCH(_xlpm.stages, _xlpm.stages, 0))))} -> Series A | F28: {=_xlfn.LET( _xlpm.stages, _xlfn._xlws.FILTER( Cleaned_Data!$H$3:$H$273, (Cleaned_Data!$G$3:$G$273>=DATE(2018,1,1))* (Cleaned_Data!$G$3:$G$273<DATE(2019,1,1))* (Cleaned_Data!$H$3:$H$273<>"")), INDEX( _xlpm.stages, MODE( MATCH(_xlpm.stages, _xlpm.stages, 0))))} -> Series A | G28: {=_xlfn.LET( _xlpm.stages, _xlfn._xlws.FILTER( Cleaned_Data!$H$3:$H$273, (Cleaned_Data!$G$3:$G$273>=DATE(2019,1,1))* (Cleaned_Data!$G$3:$G$273<DATE(2020,1,1))* (Cleaned_Data!$H$3:$H$273<>"")), INDEX( _xlpm.stages, MODE( MATCH(_xlpm.stages, _xlpm.stages, 0))))} -> Series A | H28: {=_xlfn.LET( _xlpm.stages, _xlfn._xlws.FILTER( Cleaned_Data!$H$3:$H$273, (Cleaned_Data!$G$3:$G$273>=DATE(2020,1,1))* (Cleaned_Data!$G$3:$G$273<DATE(2021,1,1))* (Cleaned_Data!$H$3:$H$273<>"")), INDEX( _xlpm.stages, MODE( MATCH(_xlpm.stages, _xlpm.stages, 0))))} -> Series A | I28: {=_xlfn.LET( _xlpm.stages, _xlfn._xlws.FILTER( Cleaned_Data!$H$3:$H$273, (Cleaned_Data!$G$3:$G$273>=DATE(2021,1,1))* (Cleaned_Data!$G$3:$G$273<DATE(2022,1,1))* (Cleaned_Data!$H$3:$H$273<>"")), INDEX( _xlpm.stages, MODE( MATCH(_xlpm.stages, _xlpm.stages, 0))))} -> Development capital | J28: {=_xlfn.LET( _xlpm.stages, _xlfn._xlws.FILTER( Cleaned_Data!$H$3:$H$273, (Cleaned_Data!$G$3:$G$273>=DATE(2022,1,1))* (Cleaned_Data!$G$3:$G$273<DATE(2023,1,1))* (Cleaned_Data!$H$3:$H$273<>"")), INDEX( _xlpm.stages, MODE( MATCH(_xlpm.stages, _xlpm.stages, 0))))} -> Seed | K28: {=_xlfn.LET( _xlpm.stages, _xlfn._xlws.FILTER( Cleaned_Data!$H$3:$H$273, (Cleaned_Data!$G$3:$G$273>=DATE(2023,1,1))* (Cleaned_Data!$G$3:$G$273<DATE(2024,1,1))* (Cleaned_Data!$H$3:$H$273<>"")), INDEX( _xlpm.stages, MODE( MATCH(_xlpm.stages, _xlpm.stages, 0))))} -> Development capital | L28: {=_xlfn.LET( _xlpm.stages, _xlfn._xlws.FILTER( Cleaned_Data!$H$3:$H$273, (Cleaned_Data!$G$3:$G$273>=DATE(2024,1,1))* (Cleaned_Data!$G$3:$G$273<DATE(2025,1,1))* (Cleaned_Data!$H$3:$H$273<>"")), INDEX( _xlpm.stages, MODE( MATCH(_xlpm.stages, _xlpm.stages, 0))))} -> Development capital | M28: {=_xlfn.LET( _xlpm.stages, _xlfn._xlws.FILTER( Cleaned_Data!$H$3:$H$273, (Cleaned_Data!$G$3:$G$273>=DATE(2025,1,1))* (Cleaned_Data!$G$3:$G$273<DATE(2026,1,1))* (Cleaned_Data!$H$3:$H$273<>"")), INDEX( _xlpm.stages, MODE( MATCH(_xlpm.stages, _xlpm.stages, 0))))} -> Development capital
B31: Investor Profile Analysis
C32: Overall | D32: Renewables | E32: LDES | F32: Hydrogen | G32: CDR | H32: Industrial Decarbonization | I32: Buildings | J32: Mobility | K32: Food&Ag
B33: Avg Existing Investor Participation (%) | C33: =AVERAGEIFS(Cleaned_Data!$P$3:$P$273,Cleaned_Data!$P$3:$P$273,"<>N/A") -> 0.18731044 | D33: =AVERAGEIFS( Cleaned_Data!$P$3:$P$273,Cleaned_Data!$F$3:$F$273, "Renewables", Cleaned_Data!$P$3:$P$273, "<>N/A") -> 0.11521851 | E33: =AVERAGEIFS( Cleaned_Data!$P$3:$P$273,Cleaned_Data!$F$3:$F$273, "LDES", Cleaned_Data!$P$3:$P$273, "<>N/A") -> 0.22132654 | F33: =AVERAGEIFS( Cleaned_Data!$P$3:$P$273,Cleaned_Data!$F$3:$F$273, "Hydrogen", Cleaned_Data!$P$3:$P$273, "<>N/A") -> 0.16882932 | G33: =AVERAGEIFS( Cleaned_Data!$P$3:$P$273,Cleaned_Data!$F$3:$F$273, "CDR", Cleaned_Data!$P$3:$P$273, "<>N/A") -> 0.20804196 | H33: =AVERAGEIFS( Cleaned_Data!$P$3:$P$273,Cleaned_Data!$F$3:$F$273, "Industrial Decarbonization", Cleaned_Data!$P$3:$P$273, "<>N/A") -> 0.20154326 | I33: =AVERAGEIFS( Cleaned_Data!$P$3:$P$273,Cleaned_Data!$F$3:$F$273, "Buildings", Cleaned_Data!$P$3:$P$273, "<>N/A") -> 0.31555556 | J33: =AVERAGEIFS( Cleaned_Data!$P$3:$P$273,Cleaned_Data!$F$3:$F$273, "Mobility", Cleaned_Data!$P$3:$P$273, "<>N/A") -> 0.10839002 | K33: =AVERAGEIFS( Cleaned_Data!$P$3:$P$273,Cleaned_Data!$F$3:$F$273, "Food & Ag", Cleaned_Data!$P$3:$P$273, "<>N/A") -> 0.24931125
B34: Avg New Investor Participation (%) | C34: =AVERAGEIFS(Cleaned_Data!$R$3:$R$273,Cleaned_Data!$R$3:$R$273,"<>N/A") -> 0.87860528 | D34: =AVERAGEIFS( Cleaned_Data!$R$3:$R$273,Cleaned_Data!$F$3:$F$273, "Renewables", Cleaned_Data!$R$3:$R$273, "<>N/A") -> 0.92494998 | E34: =AVERAGEIFS( Cleaned_Data!$R$3:$R$273,Cleaned_Data!$F$3:$F$273, "LDES", Cleaned_Data!$R$3:$R$273, "<>N/A") -> 0.90662879 | F34: =AVERAGEIFS( Cleaned_Data!$R$3:$R$273,Cleaned_Data!$F$3:$F$273, "Hydrogen", Cleaned_Data!$R$3:$R$273, "<>N/A") -> 0.87441751 | G34: =AVERAGEIFS( Cleaned_Data!$R$3:$R$273,Cleaned_Data!$F$3:$F$273, "CDR", Cleaned_Data!$R$3:$R$273, "<>N/A") -> 0.87941919 | H34: =AVERAGEIFS( Cleaned_Data!$R$3:$R$273,Cleaned_Data!$F$3:$F$273, "Industrial Decarbonization", Cleaned_Data!$R$3:$R$273, "<>N/A") -> 0.87292078 | I34: =AVERAGEIFS( Cleaned_Data!$R$3:$R$273,Cleaned_Data!$F$3:$F$273, "Buildings", Cleaned_Data!$R$3:$R$273, "<>N/A") -> 0.78974359 | J34: =AVERAGEIFS( Cleaned_Data!$R$3:$R$273,Cleaned_Data!$F$3:$F$273, "Mobility", Cleaned_Data!$R$3:$R$273, "<>N/A") -> 0.89160998 | K34: =AVERAGEIFS( Cleaned_Data!$R$3:$R$273,Cleaned_Data!$F$3:$F$273, "Food & Ag", Cleaned_Data!$R$3:$R$273, "<>N/A") -> 0.82865129
B37: # Unique Investors | C37: =COUNTA(_xlfn.UNIQUE(Investor_Analysis_Setup!E4:E1128)) -> 884
B38: Share of deals with existing investor participation | C38: =COUNTIF(Cleaned_Data!$O$3:$O$273, "Y")/COUNTIF(Cleaned_Data!$O$3:$O$273, "<>") -> 0.49077491
B39: Share of deals with new strategic investors | C39: =COUNTIF(Cleaned_Data!S3:S273,"Y")/COUNTIF(Cleaned_Data!S3:S273,"<>") -> 0.11439114
B40: Share of deals with 100% new investors | C40: =COUNTIFS(Cleaned_Data!$R$3:$R$273,"100.0%")/COUNTIF(Cleaned_Data!$R$3:$R$273,"<>") -> 0.52398524
B43: Most commonly participating investors
C44: Breakthrough Energy | D44: Temasek Holdings | E44: SOSV | F44: Collaborative Fund | G44: Safar Partners | H44: Loweracarbon Capital | I44: Climate Capital | J44: Khosla Ventures
B45: Number of Deals | C45: 10 | D45: 9 | E45: 8 | F45: 8 | G45: 7 | H45: 7 | I45: 7 | J45: 6
B47: Most commonly *new* participating investors
C48: Temasek Holdings | D48: Climate Capital | E48: Lowercarbon Capital | F48: Collaborative Fund | G48: E8
B49: Number of Deals | C49: 8 | D49: 7 | E49: 6 | F49: 6 | G49: 5
B52: Other Deal Analysis
B54: Largest deals
B55: Company | C55: Deal Size | D55: Deal Date
B56: {=_xlfn.TAKE(_xlfn._xlws.SORT(_xlfn._xlws.FILTER(CHOOSE({1,2,3},Cleaned_Data!$C$3:$C$273,Cleaned_Data!$J$3:$J$273,Cleaned_Data!$G$3:$G$273),Cleaned_Data!$J$3:$J$273>0),2,-1),5)} -> Faraday Future Intelligent Electric (NAS: FFAI) | C56: 1250 | D56: 43584
B57: Commonwealth Fusion Systems | C57: 863 | D57: 45834
B58: Terrapower | C58: 830 | D58: 44868
...

Sheet Charts
B2: CHARTS

Sheet Cleaned_Data
B2: Deal_ID | C2: Company_Name | D2: State | E2: Year Founded | F2: Sector | G2: Date | H2: Deal Stage | I2: Total Capital Raised to date | J2: Deal_Size | K2: Valuation | L2: % Debt | M2: Investors | N2: # Investors in Round | O2: Existing Investor Participation | P2: Existing Investor % | Q2: New Investor Participation | R2: New Investor % | S2: New Strategic Investor (Y/N) | T2: Philanthropic Capital (Y/N) | U2: Investor Mix
B3: 1 | C3: =IFERROR(_xlfn.XLOOKUP($B3,Raw_Data!$A$3:$A$273,Raw_Data!$B$3:$B$273),"") -> 247Solar | D3: =IFERROR(_xlfn.XLOOKUP($B3,Raw_Data!$A$3:$A$273,Raw_Data!$C$3:$C$273),"") -> Great Falls, VA | E3: =IFERROR(_xlfn.XLOOKUP($B3,Raw_Data!$A$3:$A$273,Raw_Data!$D$3:$D$273),"") -> 2015 | F3: =IFERROR(_xlfn.XLOOKUP($B3,Raw_Data!$A$3:$A$273,Raw_Data!$F$3:$F$273),"") -> Renewables | G3: =IFERROR(_xlfn.XLOOKUP($B3,Raw_Data!$A$3:$A$273,Raw_Data!$J$3:$J$273),"") -> 44895 | H3: Series A | I3: =IFERROR(_xlfn.XLOOKUP($B3,Raw_Data!$A$3:$A$273,Raw_Data!$I$3:$I$273),"") -> 12.5 | J3: =IFERROR(_xlfn.XLOOKUP($B3,Raw_Data!$A$3:$A$273,Raw_Data!$L$3:$L$273),"") -> 3.5 | K3: =IFERROR(_xlfn.XLOOKUP($B3,Raw_Data!$A$3:$A$273,Raw_Data!$M$3:$M$273),"") -> 40 | L3: =IFERROR(_xlfn.XLOOKUP($B3,Raw_Data!$A$3:$A$273,Raw_Data!$Q$3:$Q$273),"") -> 0 | M3: =IFERROR(_xlfn.XLOOKUP($B3,Raw_Data!$A$3:$A$273,Raw_Data!$R$3:$R$273),"") -> Safar Partners | N3: {=IF(M3="",0,COUNTA(_xlfn._xlws.FILTER(_xlfn.TEXTSPLIT(M3,";"), _xlfn.TEXTSPLIT(M3,";")<>"")))} -> 1 | O3: =IF(P3>0,"Y","N") -> N | P3: =IFERROR(_xlfn.XLOOKUP($B3,Raw_Data!$A$3:$A$273,Raw_Data!$V$3:$V$273),"") -> 0 | Q3: =IF(R3>0,"Y","N") -> Y | R3: =IFERROR(_xlfn.XLOOKUP($B3,Raw_Data!$A$3:$A$273,Raw_Data!$Y$3:$Y$273),"") -> 1 | S3: {=_xlfn.LET(_xlpm.s, Raw_Data!W3,_xlpm.strat, _xlfn._xlws.FILTER(REF_Setup!$B$3:$B$40, REF_Setup!$B$3:$B$40<>""),IF(OR(_xlpm.s="",_xlpm.s=0),"Unclassified",IF(SUM(--ISNUMBER(SEARCH(_xlpm.strat, _xlpm.s)))>0, "Y", "N")) )} -> N | T3: {=_xlfn.LET(_xlpm.s,M3,_xlpm.phil, _xlfn._xlws.FILTER(REF_Setup!$D$3:$D$5, REF_Setup!$D$3:$D$5<>""),IF(OR(_xlpm.s="", _xlpm.s=0),"Unclassified",IF(SUM(--ISNUMBER(SEARCH(_xlpm.phil, _xlpm.s)))>0, "Y", "N")))} -> N | U3: {=IF(M3="", "Unclassified", IF(AND(SUMPRODUCT(--ISNUMBER(SEARCH(REF_Setup!$B$3:$B$40,M3)))>0,SUMPRODUCT(--ISNUMBER(SEARCH(REF_Setup!$F$3:$F$15,M3)))>0),"Mixed",IF(SUMPRODUCT(--ISNUMBER(SEARCH(REF_Setup!$B$3:$B$40,M3)))>0,"Strategic Only",IF(SUMPRODUCT(--ISNUMBER(SEARCH(REF_Setup!$F$3:$F$15,M3)))>0,"VC Only","Unclassified"))))} -> VC Only
B4: =B3+1 -> 2 | C4: =IFERROR(_xlfn.XLOOKUP($B4,Raw_Data!$A$3:$A$273,Raw_Data!$B$3:$B$273),"") -> 247Solar | D4: =IFERROR(_xlfn.XLOOKUP($B4,Raw_Data!$A$3:$A$273,Raw_Data!$C$3:$C$273),"") -> Great Falls, VA | E4: =IFERROR(_xlfn.XLOOKUP($B4,Raw_Data!$A$3:$A$273,Raw_Data!$D$3:$D$273),"") -> 2015 | F4: =IFERROR(_xlfn.XLOOKUP($B4,Raw_Data!$A$3:$A$273,Raw_Data!$F$3:$F$273),"") -> Renewables | G4: =IFERROR(_xlfn.XLOOKUP($B4,Raw_Data!$A$3:$A$273,Raw_Data!$J$3:$J$273),"") -> 45657 | H4: Series A | I4: =IFERROR(_xlfn.XLOOKUP($B4,Raw_Data!$A$3:$A$273,Raw_Data!$I$3:$I$273),"") -> 20.5 | J4: =IFERROR(_xlfn.XLOOKUP($B4,Raw_Data!$A$3:$A$273,Raw_Data!$L$3:$L$273),"") -> 8 | K4: =IFERROR(_xlfn.XLOOKUP($B4,Raw_Data!$A$3:$A$273,Raw_Data!$M$3:$M$273),"") -> 0 | L4: =IFERROR(_xlfn.XLOOKUP($B4,Raw_Data!$A$3:$A$273,Raw_Data!$Q$3:$Q$273),"") -> 0 | M4: =IFERROR(_xlfn.XLOOKUP($B4,Raw_Data!$A$3:$A$273,Raw_Data!$R$3:$R$273),"") -> COCONUT GROVE; First Financial Bankshares; M10Lean capital; Mintz | N4: {=IF(M4="",0,COUNTA(_xlfn._xlws.FILTER(_xlfn.TEXTSPLIT(M4,";"), _xlfn.TEXTSPLIT(M4,";")<>"")))} -> 4 | O4: =IF(P4>0,"Y","N") -> N | P4: =IFERROR(_xlfn.XLOOKUP($B4,Raw_Data!$A$3:$A$273,Raw_Data!$V$3:$V$273),"") -> 0 | Q4: =IF(R4>0,"Y","N") -> Y | R4: =IFERROR(_xlfn.XLOOKUP($B4,Raw_Data!$A$3:$A$273,Raw_Data!$Y$3:$Y$273),"") -> 1 | S4: {=_xlfn.LET(_xlpm.s, Raw_Data!W4,_xlpm.strat, _xlfn._xlws.FILTER(REF_Setup!$B$3:$B$40, REF_Setup!$B$3:$B$40<>""),IF(OR(_xlpm.s="",_xlpm.s=0),"Unclassified",IF(SUM(--ISNUMBER(SEARCH(_xlpm.strat, _xlpm.s)))>0, "Y", "N")) )} -> N | T4: {=_xlfn.LET(_xlpm.s,M4,_xlpm.phil, _xlfn._xlws.FILTER(REF_Setup!$D$3:$D$5, REF_Setup!$D$3:$D$5<>""),IF(OR(_xlpm.s="", _xlpm.s=0),"Unclassified",IF(SUM(--ISNUMBER(SEARCH(_xlpm.phil, _xlpm.s)))>0, "Y", "N")))} -> N | U4: {=IF(M4="", "Unclassified", IF(AND(SUMPRODUCT(--ISNUMBER(SEARCH(REF_Setup!$B$3:$B$40,M4)))>0,SUMPRODUCT(--ISNUMBER(SEARCH(REF_Setup!$F$3:$F$15,M4)))>0),"Mixed",IF(SUMPRODUCT(--ISNUMBER(SEARCH(REF_Setup!$B$3:$B$40,M4)))>0,"Strategic Only",IF(SUMPRODUCT(--ISNUMBER(SEARCH(REF_Setup!$F$3:$F$15,M4)))>0,"VC Only","Unclassified"))))} -> VC Only
B5: =B4+1 -> 3 | C5: =IFERROR(_xlfn.XLOOKUP($B5,Raw_Data!$A$3:$A$273,Raw_Data!$B$3:$B$273),"") -> Aanika | D5: =IFERROR(_xlfn.XLOOKUP($B5,Raw_Data!$A$3:$A$273,Raw_Data!$C$3:$C$273),"") -> New York, NY | E5: =IFERROR(_xlfn.XLOOKUP($B5,Raw_Data!$A$3:$A$273,Raw_Data!$D$3:$D$273),"") -> 2018 | F5: =IFERROR(_xlfn.XLOOKUP($B5,Raw_Data!$A$3:$A$273,Raw_Data!$F$3:$F$273),"") -> Food & Ag | G5: =IFERROR(_xlfn.XLOOKUP($B5,Raw_Data!$A$3:$A$273,Raw_Data!$J$3:$J$273),"") -> 43879 | H5: Seed | I5: =IFERROR(_xlfn.XLOOKUP($B5,Raw_Data!$A$3:$A$273,Raw_Data!$I$3:$I$273),"") -> 2.63 | J5: =IFERROR(_xlfn.XLOOKUP($B5,Raw_Data!$A$3:$A$273,Raw_Data!$L$3:$L$273),"") -> 2.5 | K5: =IFERROR(_xlfn.XLOOKUP($B5,Raw_Data!$A$3:$A$273,Raw_Data!$M$3:$M$273),"") -> 7.93 | L5: =IFERROR(_xlfn.XLOOKUP($B5,Raw_Data!$A$3:$A$273,Raw_Data!$Q$3:$Q$273),"") -> 0.028 | M5: =IFERROR(_xlfn.XLOOKUP($B5,Raw_Data!$A$3:$A$273,Raw_Data!$R$3:$R$273),"") -> Alex Chung; Draper Associates; Kabir Misra; RPS Ventures; SOSV | N5: {=IF(M5="",0,COUNTA(_xlfn._xlws.FILTER(_xlfn.TEXTSPLIT(M5,";"), _xlfn.TEXTSPLIT(M5,";")<>"")))} -> 5 | O5: =IF(P5>0,"Y","N") -> N | P5: =IFERROR(_xlfn.XLOOKUP($B5,Raw_Data!$A$3:$A$273,Raw_Data!$V$3:$V$273),"") -> 0 | Q5: =IF(R5>0,"Y","N") -> Y | R5: =IFERROR(_xlfn.XLOOKUP($B5,Raw_Data!$A$3:$A$273,Raw_Data!$Y$3:$Y$273),"") -> 1 | S5: {=_xlfn.LET(_xlpm.s, Raw_Data!W5,_xlpm.strat, _xlfn._xlws.FILTER(REF_Setup!$B$3:$B$40, REF_Setup!$B$3:$B$40<>""),IF(OR(_xlpm.s="",_xlpm.s=0),"Unclassified",IF(SUM(--ISNUMBER(SEARCH(_xlpm.strat, _xlpm.s)))>0, "Y", "N")) )} -> N | T5: {=_xlfn.LET(_xlpm.s,M5,_xlpm.phil, _xlfn._xlws.FILTER(REF_Setup!$D$3:$D$5, REF_Setup!$D$3:$D$5<>""),IF(OR(_xlpm.s="", _xlpm.s=0),"Unclassified",IF(SUM(--ISNUMBER(SEARCH(_xlpm.phil, _xlpm.s)))>0, "Y", "N")))} -> N | U5: {=IF(M5="", "Unclassified", IF(AND(SUMPRODUCT(--ISNUMBER(SEARCH(REF_Setup!$B$3:$B$40,M5)))>0,SUMPRODUCT(--ISNUMBER(SEARCH(REF_Setup!$F$3:$F$15,M5)))>0),"Mixed",IF(SUMPRODUCT(--ISNUMBER(SEARCH(REF_Setup!$B$3:$B$40,M5)))>0,"Strategic Only",IF(SUMPRODUCT(--ISNUMBER(SEARCH(REF_Setup!$F$3:$F$15,M5)))>0,"VC Only","Unclassified"))))} -> VC Only
B6: =B5+1 -> 4 | C6: =IFERROR(_xlfn.XLOOKUP($B6,Raw_Data!$A$3:$A$273,Raw_Data!$B$3:$B$273),"") -> Aces Delta | D6: =IFERROR(_xlfn.XLOOKUP($B6,Raw_Data!$A$3:$A$273,Raw_Data!$C$3:$C$273),"") -> Holladay, UT | E6: =IFERROR(_xlfn.XLOOKUP($B6,Raw_Data!$A$3:$A$273,Raw_Data!$D$3:$D$273),"") -> 2019 | F6: =IFERROR(_xlfn.XLOOKUP($B6,Raw_Data!$A$3:$A$273,Raw_Data!$F$3:$F$273),"") -> Hydrogen | G6: =IFERROR(_xlfn.XLOOKUP($B6,Raw_Data!$A$3:$A$273,Raw_Data!$J$3:$J$273),"") -> 44721 | H6: Development capital | I6: =IFERROR(_xlfn.XLOOKUP($B6,Raw_Data!$A$3:$A$273,Raw_Data!$I$3:$I$273),"") -> 650 | J6: =IFERROR(_xlfn.XLOOKUP($B6,Raw_Data!$A$3:$A$273,Raw_Data!$L$3:$L$273),"") -> 650 | K6: =IFERROR(_xlfn.XLOOKUP($B6,Raw_Data!$A$3:$A$273,Raw_Data!$M$3:$M$273),"") -> 0 | L6: =IFERROR(_xlfn.XLOOKUP($B6,Raw_Data!$A$3:$A$273,Raw_Data!$Q$3:$Q$273),"") -> 0 | M6: =IFERROR(_xlfn.XLOOKUP($B6,Raw_Data!$A$3:$A$273,Raw_Data!$R$3:$R$273),"") -> Alberta Investment Management; GIC Private; Haddington Ventures, Manulife Financial; Onterio Teachers Pension Plan | N6: {=IF(M6="",0,COUNTA(_xlfn._xlws.FILTER(_xlfn.TEXTSPLIT(M6,";"), _xlfn.TEXTSPLIT(M6,";")<>"")))} -> 4 | O6: =IF(P6>0,"Y","N") -> N | P6: =IFERROR(_xlfn.XLOOKUP($B6,Raw_Data!$A$3:$A$273,Raw_Data!$V$3:$V$273),"") -> 0 | Q6: =IF(R6>0,"Y","N") -> Y | R6: =IFERROR(_xlfn.XLOOKUP($B6,Raw_Data!$A$3:$A$273,Raw_Data!$Y$3:$Y$273),"") -> 1 | S6: {=_xlfn.LET(_xlpm.s, Raw_Data!W6,_xlpm.strat, _xlfn._xlws.FILTER(REF_Setup!$B$3:$B$40, REF_Setup!$B$3:$B$40<>""),IF(OR(_xlpm.s="",_xlpm.s=0),"Unclassified",IF(SUM(--ISNUMBER(SEARCH(_xlpm.strat, _xlpm.s)))>0, "Y", "N")) )} -> N | T6: {=_xlfn.LET(_xlpm.s,M6,_xlpm.phil, _xlfn._xlws.FILTER(REF_Setup!$D$3:$D$5, REF_Setup!$D$3:$D$5<>""),IF(OR(_xlpm.s="", _xlpm.s=0),"Unclassified",IF(SUM(--ISNUMBER(SEARCH(_xlpm.phil, _xlpm.s)))>0, "Y", "N")))} -> N | U6: {=IF(M6="", "Unclassified", IF(AND(SUMPRODUCT(--ISNUMBER(SEARCH(REF_Setup!$B$3:$B$40,M6)))>0,SUMPRODUCT(--ISNUMBER(SEARCH(REF_Setup!$F$3:$F$15,M6)))>0),"Mixed",IF(SUMPRODUCT(--ISNUMBER(SEARCH(REF_Setup!$B$3:$B$40,M6)))>0,"Strategic Only",IF(SUMPRODUCT(--ISNUMBER(SEARCH(REF_Setup!$F$3:$F$15,M6)))>0,"VC Only","Unclassified"))))} -> VC Only
B7: =B6+1 -> 5 | C7: =IFERROR(_xlfn.XLOOKUP($B7,Raw_Data!$A$3:$A$273,Raw_Data!$B$3:$B$273),"") -> Addis Energy | D7: =IFERROR(_xlfn.XLOOKUP($B7,Raw_Data!$A$3:$A$273,Raw_Data!$C$3:$C$273),"") -> Somewille, MA | E7: =IFERROR(_xlfn.XLOOKUP($B7,Raw_Data!$A$3:$A$273,Raw_Data!$D$3:$D$273),"") -> 2024 | F7: =IFERROR(_xlfn.XLOOKUP($B7,Raw_Data!$A$3:$A$273,Raw_Data!$F$3:$F$273),"") -> Hydrogen | G7: =IFERROR(_xlfn.XLOOKUP($B7,Raw_Data!$A$3:$A$273,Raw_Data!$J$3:$J$273),"") -> 45978 | I7: =IFERROR(_xlfn.XLOOKUP($B7,Raw_Data!$A$3:$A$273,Raw_Data!$I$3:$I$273),"") -> 17.31 | J7: =IFERROR(_xlfn.XLOOKUP($B7,Raw_Data!$A$3:$A$273,Raw_Data!$L$3:$L$273),"") -> 8.41 | K7: =IFERROR(_xlfn.XLOOKUP($B7,Raw_Data!$A$3:$A$273,Raw_Data!$M$3:$M$273),"") -> 22 | L7: =IFERROR(_xlfn.XLOOKUP($B7,Raw_Data!$A$3:$A$273,Raw_Data!$Q$3:$Q$273),"") -> 0 | M7: =IFERROR(_xlfn.XLOOKUP($B7,Raw_Data!$A$3:$A$273,Raw_Data!$R$3:$R$273),"") -> At One Ventures; Engine Ventures; Pillar VC | N7: {=IF(M7="",0,COUNTA(_xlfn._xlws.FILTER(_xlfn.TEXTSPLIT(M7,";"), _xlfn.TEXTSPLIT(M7,";")<>"")))} -> 3 | O7: =IF(P7>0,"Y","N") -> Y | P7: =IFERROR(_xlfn.XLOOKUP($B7,Raw_Data!$A$3:$A$273,Raw_Data!$V$3:$V$273),"") -> 0.66666667 | Q7: =IF(R7>0,"Y","N") -> Y | R7: =IFERROR(_xlfn.XLOOKUP($B7,Raw_Data!$A$3:$A$273,Raw_Data!$Y$3:$Y$273),"") -> 0.33333333 | S7: {=_xlfn.LET(_xlpm.s, Raw_Data!W7,_xlpm.strat, _xlfn._xlws.FILTER(REF_Setup!$B$3:$B$40, REF_Setup!$B$3:$B$40<>""),IF(OR(_xlpm.s="",_xlpm.s=0),"Unclassified",IF(SUM(--ISNUMBER(SEARCH(_xlpm.strat, _xlpm.s)))>0, "Y", "N")) )} -> N | T7: {=_xlfn.LET(_xlpm.s,M7,_xlpm.phil, _xlfn._xlws.FILTER(REF_Setup!$D$3:$D$5, REF_Setup!$D$3:$D$5<>""),IF(OR(_xlpm.s="", _xlpm.s=0),"Unclassified",IF(SUM(--ISNUMBER(SEARCH(_xlpm.phil, _xlpm.s)))>0, "Y", "N")))} -> N | U7: {=IF(M7="", "Unclassified", IF(AND(SUMPRODUCT(--ISNUMBER(SEARCH(REF_Setup!$B$3:$B$40,M7)))>0,SUMPRODUCT(--ISNUMBER(SEARCH(REF_Setup!$F$3:$F$15,M7)))>0),"Mixed",IF(SUMPRODUCT(--ISNUMBER(SEARCH(REF_Setup!$B$3:$B$40,M7)))>0,"Strategic Only",IF(SUMPRODUCT(--ISNUMBER(SEARCH(REF_Setup!$F$3:$F$15,M7)))>0,"VC Only","Unclassified"))))} -> VC Only
B8: =B7+1 -> 6 | C8: =IFERROR(_xlfn.XLOOKUP($B8,Raw_Data!$A$3:$A$273,Raw_Data!$B$3:$B$273),"") -> Advanced Battery Concepts | D8: =IFERROR(_xlfn.XLOOKUP($B8,Raw_Data!$A$3:$A$273,Raw_Data!$C$3:$C$273),"") -> Clare, MI | E8: =IFERROR(_xlfn.XLOOKUP($B8,Raw_Data!$A$3:$A$273,Raw_Data!$D$3:$D$273),"") -> 2008 | F8: =IFERROR(_xlfn.XLOOKUP($B8,Raw_Data!$A$3:$A$273,Raw_Data!$F$3:$F$273),"") -> LDES | G8: =IFERROR(_xlfn.XLOOKUP($B8,Raw_Data!$A$3:$A$273,Raw_Data!$J$3:$J$273),"") -> 42207 | H8: Series A | I8: =IFERROR(_xlfn.XLOOKUP($B8,Raw_Data!$A$3:$A$273,Raw_Data!$I$3:$I$273),"") -> 8.76 | J8: =IFERROR(_xlfn.XLOOKUP($B8,Raw_Data!$A$3:$A$273,Raw_Data!$L$3:$L$273),"") -> 3.09 | K8: =IFERROR(_xlfn.XLOOKUP($B8,Raw_Data!$A$3:$A$273,Raw_Data!$M$3:$M$273),"") -> 0 | L8: =IFERROR(_xlfn.XLOOKUP($B8,Raw_Data!$A$3:$A$273,Raw_Data!$Q$3:$Q$273),"") -> 0 | M8: =IFERROR(_xlfn.XLOOKUP($B8,Raw_Data!$A$3:$A$273,Raw_Data!$R$3:$R$273),"") -> BlueWater Angels | N8: {=IF(M8="",0,COUNTA(_xlfn._xlws.FILTER(_xlfn.TEXTSPLIT(M8,";"), _xlfn.TEXTSPLIT(M8,";")<>"")))} -> 1 | O8: =IF(P8>0,"Y","N") -> Y | P8: =IFERROR(_xlfn.XLOOKUP($B8,Raw_Data!$A$3:$A$273,Raw_Data!$V$3:$V$273),"") -> 1 | Q8: =IF(R8>0,"Y","N") -> Y | R8: =IFERROR(_xlfn.XLOOKUP($B8,Raw_Data!$A$3:$A$273,Raw_Data!$Y$3:$Y$273),"") -> N/A | S8: {=_xlfn.LET(_xlpm.s, Raw_Data!W8,_xlpm.strat, _xlfn._xlws.FILTER(REF_Setup!$B$3:$B$40, REF_Setup!$B$3:$B$40<>""),IF(OR(_xlpm.s="",_xlpm.s=0),"Unclassified",IF(SUM(--ISNUMBER(SEARCH(_xlpm.strat, _xlpm.s)))>0, "Y", "N")) )} -> Unclassified | T8: {=_xlfn.LET(_xlpm.s,M8,_xlpm.phil, _xlfn._xlws.FILTER(REF_Setup!$D$3:$D$5, REF_Setup!$D$3:$D$5<>""),IF(OR(_xlpm.s="", _xlpm.s=0),"Unclassified",IF(SUM(--ISNUMBER(SEARCH(_xlpm.phil, _xlpm.s)))>0, "Y", "N")))} -> N | U8: {=IF(M8="", "Unclassified", IF(AND(SUMPRODUCT(--ISNUMBER(SEARCH(REF_Setup!$B$3:$B$40,M8)))>0,SUMPRODUCT(--ISNUMBER(SEARCH(REF_Setup!$F$3:$F$15,M8)))>0),"Mixed",IF(SUMPRODUCT(--ISNUMBER(SEARCH(REF_Setup!$B$3:$B$40,M8)))>0,"Strategic Only",IF(SUMPRODUCT(--ISNUMBER(SEARCH(REF_Setup!$F$3:$F$15,M8)))>0,"VC Only","Unclassified"))))} -> Unclassified
B9: =B8+1 -> 7 | C9: =IFERROR(_xlfn.XLOOKUP($B9,Raw_Data!$A$3:$A$273,Raw_Data!$B$3:$B$273),"") -> Advanced Battery Concepts | D9: =IFERROR(_xlfn.XLOOKUP($B9,Raw_Data!$A$3:$A$273,Raw_Data!$C$3:$C$273),"") -> Clare, MI | E9: =IFERROR(_xlfn.XLOOKUP($B9,Raw_Data!$A$3:$A$273,Raw_Data!$D$3:$D$273),"") -> 2008 | F9: =IFERROR(_xlfn.XLOOKUP($B9,Raw_Data!$A$3:$A$273,Raw_Data!$F$3:$F$273),"") -> LDES | G9: =IFERROR(_xlfn.XLOOKUP($B9,Raw_Data!$A$3:$A$273,Raw_Data!$J$3:$J$273),"") -> 42699 | H9: Series A | I9: =IFERROR(_xlfn.XLOOKUP($B9,Raw_Data!$A$3:$A$273,Raw_Data!$I$3:$I$273),"") -> 11.88 | J9: =IFERROR(_xlfn.XLOOKUP($B9,Raw_Data!$A$3:$A$273,Raw_Data!$L$3:$L$273),"") -> 3.12 | K9: =IFERROR(_xlfn.XLOOKUP($B9,Raw_Data!$A$3:$A$273,Raw_Data!$M$3:$M$273),"") -> 0 | L9: =IFERROR(_xlfn.XLOOKUP($B9,Raw_Data!$A$3:$A$273,Raw_Data!$Q$3:$Q$273),"") -> 0 | M9: =IFERROR(_xlfn.XLOOKUP($B9,Raw_Data!$A$3:$A$273,Raw_Data!$R$3:$R$273),"") -> BlueWater Angels; RSVP Ventures | N9: {=IF(M9="",0,COUNTA(_xlfn._xlws.FILTER(_xlfn.TEXTSPLIT(M9,";"), _xlfn.TEXTSPLIT(M9,";")<>"")))} -> 2 | O9: =IF(P9>0,"Y","N") -> Y | P9: =IFERROR(_xlfn.XLOOKUP($B9,Raw_Data!$A$3:$A$273,Raw_Data!$V$3:$V$273),"") -> 0.5 | Q9: =IF(R9>0,"Y","N") -> Y | R9: =IFERROR(_xlfn.XLOOKUP($B9,Raw_Data!$A$3:$A$273,Raw_Data!$Y$3:$Y$273),"") -> 0.5 | S9: {=_xlfn.LET(_xlpm.s, Raw_Data!W9,_xlpm.strat, _xlfn._xlws.FILTER(REF_Setup!$B$3:$B$40, REF_Setup!$B$3:$B$40<>""),IF(OR(_xlpm.s="",_xlpm.s=0),"Unclassified",IF(SUM(--ISNUMBER(SEARCH(_xlpm.strat, _xlpm.s)))>0, "Y", "N")) )} -> N | T9: {=_xlfn.LET(_xlpm.s,M9,_xlpm.phil, _xlfn._xlws.FILTER(REF_Setup!$D$3:$D$5, REF_Setup!$D$3:$D$5<>""),IF(OR(_xlpm.s="", _xlpm.s=0),"Unclassified",IF(SUM(--ISNUMBER(SEARCH(_xlpm.phil, _xlpm.s)))>0, "Y", "N")))} -> N | U9: {=IF(M9="", "Unclassified", IF(AND(SUMPRODUCT(--ISNUMBER(SEARCH(REF_Setup!$B$3:$B$40,M9)))>0,SUMPRODUCT(--ISNUMBER(SEARCH(REF_Setup!$F$3:$F$15,M9)))>0),"Mixed",IF(SUMPRODUCT(--ISNUMBER(SEARCH(REF_Setup!$B$3:$B$40,M9)))>0,"Strategic Only",IF(SUMPRODUCT(--ISNUMBER(SEARCH(REF_Setup!$F$3:$F$15,M9)))>0,"VC Only","Unclassified"))))} -> VC Only
B10: =B9+1 -> 8 | C10: =IFERROR(_xlfn.XLOOKUP($B10,Raw_Data!$A$3:$A$273,Raw_Data!$B$3:$B$273),"") -> Aither Systems | D10: =IFERROR(_xlfn.XLOOKUP($B10,Raw_Data!$A$3:$A$273,Raw_Data!$C$3:$C$273),"") -> Alien, TX | E10: =IFERROR(_xlfn.XLOOKUP($B10,Raw_Data!$A$3:$A$273,Raw_Data!$D$3:$D$273),"") -> 0 | F10: =IFERROR(_xlfn.XLOOKUP($B10,Raw_Data!$A$3:$A$273,Raw_Data!$F$3:$F$273),"") -> LDES | G10: =IFERROR(_xlfn.XLOOKUP($B10,Raw_Data!$A$3:$A$273,Raw_Data!$J$3:$J$273),"") -> 45292 | H10: Development capital | I10: =IFERROR(_xlfn.XLOOKUP($B10,Raw_Data!$A$3:$A$273,Raw_Data!$I$3:$I$273),"") -> 0 | J10: =IFERROR(_xlfn.XLOOKUP($B10,Raw_Data!$A$3:$A$273,Raw_Data!$L$3:$L$273),"") -> 0 | K10: =IFERROR(_xlfn.XLOOKUP($B10,Raw_Data!$A$3:$A$273,Raw_Data!$M$3:$M$273),"") -> 0 | L10: =IFERROR(_xlfn.XLOOKUP($B10,Raw_Data!$A$3:$A$273,Raw_Data!$Q$3:$Q$273),"") -> N/A | M10: =IFERROR(_xlfn.XLOOKUP($B10,Raw_Data!$A$3:$A$273,Raw_Data!$R$3:$R$273),"") -> Encap Investments | N10: {=IF(M10="",0,COUNTA(_xlfn._xlws.FILTER(_xlfn.TEXTSPLIT(M10,";"), _xlfn.TEXTSPLIT(M10,";")<>"")))} -> 1 | O10: =IF(P10>0,"Y","N") -> N | P10: =IFERROR(_xlfn.XLOOKUP($B10,Raw_Data!$A$3:$A$273,Raw_Data!$V$3:$V$273),"") -> 0 | Q10: =IF(R10>0,"Y","N") -> Y | R10: =IFERROR(_xlfn.XLOOKUP($B10,Raw_Data!$A$3:$A$273,Raw_Data!$Y$3:$Y$273),"") -> 1 | S10: {=_xlfn.LET(_xlpm.s, Raw_Data!W10,_xlpm.strat, _xlfn._xlws.FILTER(REF_Setup!$B$3:$B$40, REF_Setup!$B$3:$B$40<>""),IF(OR(_xlpm.s="",_xlpm.s=0),"Unclassified",IF(SUM(--ISNUMBER(SEARCH(_xlpm.strat, _xlpm.s)))>0, "Y", "N")) )} -> N | T10: {=_xlfn.LET(_xlpm.s,M10,_xlpm.phil, _xlfn._xlws.FILTER(REF_Setup!$D$3:$D$5, REF_Setup!$D$3:$D$5<>""),IF(OR(_xlpm.s="", _xlpm.s=0),"Unclassified",IF(SUM(--ISNUMBER(SEARCH(_xlpm.phil, _xlpm.s)))>0, "Y", "N")))} -> N | U10: {=IF(M10="", "Unclassified", IF(AND(SUMPRODUCT(--ISNUMBER(SEARCH(REF_Setup!$B$3:$B$40,M10)))>0,SUMPRODUCT(--ISNUMBER(SEARCH(REF_Setup!$F$3:$F$15,M10)))>0),"Mixed",IF(SUMPRODUCT(--ISNUMBER(SEARCH(REF_Setup!$B$3:$B$40,M10)))>0,"Strategic Only",IF(SUMPRODUCT(--ISNUMBER(SEARCH(REF_Setup!$F$3:$F$15,M10)))>0,"VC Only","Unclassified"))))} -> VC Only
B11: =B10+1 -> 9 | C11: =IFERROR(_xlfn.XLOOKUP($B11,Raw_Data!$A$3:$A$273,Raw_Data!$B$3:$B$273),"") -> Alva Energy (Commercial Services) | D11: =IFERROR(_xlfn.XLOOKUP($B11,Raw_Data!$A$3:$A$273,Raw_Data!$C$3:$C$273),"") -> Cambridge, MA | E11: =IFERROR(_xlfn.XLOOKUP($B11,Raw_Data!$A$3:$A$273,Raw_Data!$D$3:$D$273),"") -> 2023 | F11: =IFERROR(_xlfn.XLOOKUP($B11,Raw_Data!$A$3:$A$273,Raw_Data!$F$3:$F$273),"") -> Renewables | G11: =IFERROR(_xlfn.XLOOKUP($B11,Raw_Data!$A$3:$A$273,Raw_Data!$J$3:$J$273),"") -> 45658 | H11: Development capital | I11: =IFERROR(_xlfn.XLOOKUP($B11,Raw_Data!$A$3:$A$273,Raw_Data!$I$3:$I$273),"") -> 0 | J11: =IFERROR(_xlfn.XLOOKUP($B11,Raw_Data!$A$3:$A$273,Raw_Data!$L$3:$L$273),"") -> 0 | K11: =IFERROR(_xlfn.XLOOKUP($B11,Raw_Data!$A$3:$A$273,Raw_Data!$M$3:$M$273),"") -> 0 | L11: =IFERROR(_xlfn.XLOOKUP($B11,Raw_Data!$A$3:$A$273,Raw_Data!$Q$3:$Q$273),"") -> N/A | M11: =IFERROR(_xlfn.XLOOKUP($B11,Raw_Data!$A$3:$A$273,Raw_Data!$R$3:$R$273),"") -> NGP Energy Capital Management | N11: {=IF(M11="",0,COUNTA(_xlfn._xlws.FILTER(_xlfn.TEXTSPLIT(M11,";"), _xlfn.TEXTSPLIT(M11,";")<>"")))} -> 1 | O11: =IF(P11>0,"Y","N") -> N | P11: =IFERROR(_xlfn.XLOOKUP($B11,Raw_Data!$A$3:$A$273,Raw_Data!$V$3:$V$273),"") -> 0 | Q11: =IF(R11>0,"Y","N") -> Y | R11: =IFERROR(_xlfn.XLOOKUP($B11,Raw_Data!$A$3:$A$273,Raw_Data!$Y$3:$Y$273),"") -> 1 | S11: {=_xlfn.LET(_xlpm.s, Raw_Data!W11,_xlpm.strat, _xlfn._xlws.FILTER(REF_Setup!$B$3:$B$40, REF_Setup!$B$3:$B$40<>""),IF(OR(_xlpm.s="",_xlpm.s=0),"Unclassified",IF(SUM(--ISNUMBER(SEARCH(_xlpm.strat, _xlpm.s)))>0, "Y", "N")) )} -> N | T11: {=_xlfn.LET(_xlpm.s,M11,_xlpm.phil, _xlfn._xlws.FILTER(REF_Setup!$D$3:$D$5, REF_Setup!$D$3:$D$5<>""),IF(OR(_xlpm.s="", _xlpm.s=0),"Unclassified",IF(SUM(--ISNUMBER(SEARCH(_xlpm.phil, _xlpm.s)))>0, "Y", "N")))} -> N | U11: {=IF(M11="", "Unclassified", IF(AND(SUMPRODUCT(--ISNUMBER(SEARCH(REF_Setup!$B$3:$B$40,M11)))>0,SUMPRODUCT(--ISNUMBER(SEARCH(REF_Setup!$F$3:$F$15,M11)))>0),"Mixed",IF(SUMPRODUCT(--ISNUMBER(SEARCH(REF_Setup!$B$3:$B$40,M11)))>0,"Strategic Only",IF(SUMPRODUCT(--ISNUMBER(SEARCH(REF_Setup!$F$3:$F$15,M11)))>0,"VC Only","Unclassified"))))} -> VC Only
B12: =B11+1 -> 10 | C12: =IFERROR(_xlfn.XLOOKUP($B12,Raw_Data!$A$3:$A$273,Raw_Data!$B$3:$B$273),"") -> Amai (Food Products) | D12: =IFERROR(_xlfn.XLOOKUP($B12,Raw_Data!$A$3:$A$273,Raw_Data!$C$3:$C$273),"") -> Vista, CA | E12: =IFERROR(_xlfn.XLOOKUP($B12,Raw_Data!$A$3:$A$273,Raw_Data!$D$3:$D$273),"") -> 2020 | F12: =IFERROR(_xlfn.XLOOKUP($B12,Raw_Data!$A$3:$A$273,Raw_Data!$F$3:$F$273),"") -> Food & Ag | G12: =IFERROR(_xlfn.XLOOKUP($B12,Raw_Data!$A$3:$A$273,Raw_Data!$J$3:$J$273),"") -> 44270 | I12: =IFERROR(_xlfn.XLOOKUP($B12,Raw_Data!$A$3:$A$273,Raw_Data!$I$3:$I$273),"") -> 0.2 | J12: =IFERROR(_xlfn.XLOOKUP($B12,Raw_Data!$A$3:$A$273,Raw_Data!$L$3:$L$273),"") -> 0 | K12: =IFERROR(_xlfn.XLOOKUP($B12,Raw_Data!$A$3:$A$273,Raw_Data!$M$3:$M$273),"") -> 0 | L12: =IFERROR(_xlfn.XLOOKUP($B12,Raw_Data!$A$3:$A$273,Raw_Data!$Q$3:$Q$273),"") -> N/A | M12: =IFERROR(_xlfn.XLOOKUP($B12,Raw_Data!$A$3:$A$273,Raw_Data!$R$3:$R$273),"") -> Chartered Investment Managers | N12: {=IF(M12="",0,COUNTA(_xlfn._xlws.FILTER(_xlfn.TEXTSPLIT(M12,";"), _xlfn.TEXTSPLIT(M12,";")<>"")))} -> 1 | O12: =IF(P12>0,"Y","N") -> N | P12: =IFERROR(_xlfn.XLOOKUP($B12,Raw_Data!$A$3:$A$273,Raw_Data!$V$3:$V$273),"") -> 0 | Q12: =IF(R12>0,"Y","N") -> Y | R12: =IFERROR(_xlfn.XLOOKUP($B12,Raw_Data!$A$3:$A$273,Raw_Data!$Y$3:$Y$273),"") -> 1 | S12: {=_xlfn.LET(_xlpm.s, Raw_Data!W12,_xlpm.strat, _xlfn._xlws.FILTER(REF_Setup!$B$3:$B$40, REF_Setup!$B$3:$B$40<>""),IF(OR(_xlpm.s="",_xlpm.s=0),"Unclassified",IF(SUM(--ISNUMBER(SEARCH(_xlpm.strat, _xlpm.s)))>0, "Y", "N")) )} -> N | T12: {=_xlfn.LET(_xlpm.s,M12,_xlpm.phil, _xlfn._xlws.FILTER(REF_Setup!$D$3:$D$5, REF_Setup!$D$3:$D$5<>""),IF(OR(_xlpm.s="", _xlpm.s=0),"Unclassified",IF(SUM(--ISNUMBER(SEARCH(_xlpm.phil, _xlpm.s)))>0, "Y", "N")))} -> N | U12: {=IF(M12="", "Unclassified", IF(AND(SUMPRODUCT(--ISNUMBER(SEARCH(REF_Setup!$B$3:$B$40,M12)))>0,SUMPRODUCT(--ISNUMBER(SEARCH(REF_Setup!$F$3:$F$15,M12)))>0),"Mixed",IF(SUMPRODUCT(--ISNUMBER(SEARCH(REF_Setup!$B$3:$B$40,M12)))>0,"Strategic Only",IF(SUMPRODUCT(--ISNUMBER(SEARCH(REF_Setup!$F$3:$F$15,M12)))>0,"VC Only","Unclassified"))))} -> VC Only
B13: =B12+1 -> 11 | C13: =IFERROR(_xlfn.XLOOKUP($B13,Raw_Data!$A$3:$A$273,Raw_Data!$B$3:$B$273),"") -> Amber Kinetics | D13: =IFERROR(_xlfn.XLOOKUP($B13,Raw_Data!$A$3:$A$273,Raw_Data!$C$3:$C$273),"") -> Union City, CA | E13: =IFERROR(_xlfn.XLOOKUP($B13,Raw_Data!$A$3:$A$273,Raw_Data!$D$3:$D$273),"") -> 2009 | F13: =IFERROR(_xlfn.XLOOKUP($B13,Raw_Data!$A$3:$A$273,Raw_Data!$F$3:$F$273),"") -> LDES | G13: =IFERROR(_xlfn.XLOOKUP($B13,Raw_Data!$A$3:$A$273,Raw_Data!$J$3:$J$273),"") -> 45474 | H13: Development capital | I13: =IFERROR(_xlfn.XLOOKUP($B13,Raw_Data!$A$3:$A$273,Raw_Data!$I$3:$I$273),"") -> 46.98 | J13: =IFERROR(_xlfn.XLOOKUP($B13,Raw_Data!$A$3:$A$273,Raw_Data!$L$3:$L$273),"") -> 0 | K13: =IFERROR(_xlfn.XLOOKUP($B13,Raw_Data!$A$3:$A$273,Raw_Data!$M$3:$M$273),"") -> 0 | L13: =IFERROR(_xlfn.XLOOKUP($B13,Raw_Data!$A$3:$A$273,Raw_Data!$Q$3:$Q$273),"") -> N/A | M13: =IFERROR(_xlfn.XLOOKUP($B13,Raw_Data!$A$3:$A$273,Raw_Data!$R$3:$R$273),"") -> Innova Capital Partners | N13: {=IF(M13="",0,COUNTA(_xlfn._xlws.FILTER(_xlfn.TEXTSPLIT(M13,";"), _xlfn.TEXTSPLIT(M13,";")<>"")))} -> 1 | O13: =IF(P13>0,"Y","N") -> N | P13: =IFERROR(_xlfn.XLOOKUP($B13,Raw_Data!$A$3:$A$273,Raw_Data!$V$3:$V$273),"") -> 0 | Q13: =IF(R13>0,"Y","N") -> Y | R13: =IFERROR(_xlfn.XLOOKUP($B13,Raw_Data!$A$3:$A$273,Raw_Data!$Y$3:$Y$273),"") -> 1 | S13: {=_xlfn.LET(_xlpm.s, Raw_Data!W13,_xlpm.strat, _xlfn._xlws.FILTER(REF_Setup!$B$3:$B$40, REF_Setup!$B$3:$B$40<>""),IF(OR(_xlpm.s="",_xlpm.s=0),"Unclassified",IF(SUM(--ISNUMBER(SEARCH(_xlpm.strat, _xlpm.s)))>0, "Y", "N")) )} -> N | T13: {=_xlfn.LET(_xlpm.s,M13,_xlpm.phil, _xlfn._xlws.FILTER(REF_Setup!$D$3:$D$5, REF_Setup!$D$3:$D$5<>""),IF(OR(_xlpm.s="", _xlpm.s=0),"Unclassified",IF(SUM(--ISNUMBER(SEARCH(_xlpm.phil, _xlpm.s)))>0, "Y", "N")))} -> N | U13: {=IF(M13="", "Unclassified", IF(AND(SUMPRODUCT(--ISNUMBER(SEARCH(REF_Setup!$B$3:$B$40,M13)))>0,SUMPRODUCT(--ISNUMBER(SEARCH(REF_Setup!$F$3:$F$15,M13)))>0),"Mixed",IF(SUMPRODUCT(--ISNUMBER(SEARCH(REF_Setup!$B$3:$B$40,M13)))>0,"Strategic Only",IF(SUMPRODUCT(--ISNUMBER(SEARCH(REF_Setup!$F$3:$F$15,M13)))>0,"VC Only","Unclassified"))))} -> VC Only
B14: =B13+1 -> 12 | C14: =IFERROR(_xlfn.XLOOKUP($B14,Raw_Data!$A$3:$A$273,Raw_Data!$B$3:$B$273),"") -> Amogy | D14: =IFERROR(_xlfn.XLOOKUP($B14,Raw_Data!$A$3:$A$273,Raw_Data!$C$3:$C$273),"") -> New York, NY | E14: =IFERROR(_xlfn.XLOOKUP($B14,Raw_Data!$A$3:$A$273,Raw_Data!$D$3:$D$273),"") -> 2020 | F14: =IFERROR(_xlfn.XLOOKUP($B14,Raw_Data!$A$3:$A$273,Raw_Data!$F$3:$F$273),"") -> Hydrogen | G14: =IFERROR(_xlfn.XLOOKUP($B14,Raw_Data!$A$3:$A$273,Raw_Data!$J$3:$J$273),"") -> 45002 | H14: Series B | I14: =IFERROR(_xlfn.XLOOKUP($B14,Raw_Data!$A$3:$A$273,Raw_Data!$I$3:$I$273),"") -> 207.94 | J14: =IFERROR(_xlfn.XLOOKUP($B14,Raw_Data!$A$3:$A$273,Raw_Data!$L$3:$L$273),"") -> 139 | K14: =IFERROR(_xlfn.XLOOKUP($B14,Raw_Data!$A$3:$A$273,Raw_Data!$M$3:$M$273),"") -> 589 | L14: =IFERROR(_xlfn.XLOOKUP($B14,Raw_Data!$A$3:$A$273,Raw_Data!$Q$3:$Q$273),"") -> 0 | M14: =IFERROR(_xlfn.XLOOKUP($B14,Raw_Data!$A$3:$A$273,Raw_Data!$R$3:$R$273),"") -> AP Ventures; Aramco Ventures; DCVC; Guernsey Holdings; Korea Zinc; Mitsui & Company; MOL PLUS; SK Innovation; Temasek Holdings; Yanmar Holdings; Zeon Ventures | N14: {=IF(M14="",0,COUNTA(_xlfn._xlws.FILTER(_xlfn.TEXTSPLIT(M14,";"), _xlfn.TEXTSPLIT(M14,";")<>"")))} -> 11 | O14: =IF(P14>0,"Y","N") -> Y | P14: =IFERROR(_xlfn.XLOOKUP($B14,Raw_Data!$A$3:$A$273,Raw_Data!$V$3:$V$273),"") -> 0.36363636 | Q14: =IF(R14>0,"Y","N") -> Y | R14: =IFERROR(_xlfn.XLOOKUP($B14,Raw_Data!$A$3:$A$273,Raw_Data!$Y$3:$Y$273),"") -> 0.63636364 | S14: {=_xlfn.LET(_xlpm.s, Raw_Data!W14,_xlpm.strat, _xlfn._xlws.FILTER(REF_Setup!$B$3:$B$40, REF_Setup!$B$3:$B$40<>""),IF(OR(_xlpm.s="",_xlpm.s=0),"Unclassified",IF(SUM(--ISNUMBER(SEARCH(_xlpm.strat, _xlpm.s)))>0, "Y", "N")) )} -> N | T14: {=_xlfn.LET(_xlpm.s,M14,_xlpm.phil, _xlfn._xlws.FILTER(REF_Setup!$D$3:$D$5, REF_Setup!$D$3:$D$5<>""),IF(OR(_xlpm.s="", _xlpm.s=0),"Unclassified",IF(SUM(--ISNUMBER(SEARCH(_xlpm.phil, _xlpm.s)))>0, "Y", "N")))} -> N | U14: {=IF(M14="", "Unclassified", IF(AND(SUMPRODUCT(--ISNUMBER(SEARCH(REF_Setup!$B$3:$B$40,M14)))>0,SUMPRODUCT(--ISNUMBER(SEARCH(REF_Setup!$F$3:$F$15,M14)))>0),"Mixed",IF(SUMPRODUCT(--ISNUMBER(SEARCH(REF_Setup!$B$3:$B$40,M14)))>0,"Strategic Only",IF(SUMPRODUCT(--ISNUMBER(SEARCH(REF_Setup!$F$3:$F$15,M14)))>0,"VC Only","Unclassified"))))} -> Mixed
B15: =B14+1 -> 13 | C15: =IFERROR(_xlfn.XLOOKUP($B15,Raw_Data!$A$3:$A$273,Raw_Data!$B$3:$B$273),"") -> Amogy | D15: =IFERROR(_xlfn.XLOOKUP($B15,Raw_Data!$A$3:$A$273,Raw_Data!$C$3:$C$273),"") -> New York, NY | E15: =IFERROR(_xlfn.XLOOKUP($B15,Raw_Data!$A$3:$A$273,Raw_Data!$D$3:$D$273),"") -> 2020 | F15: =IFERROR(_xlfn.XLOOKUP($B15,Raw_Data!$A$3:$A$273,Raw_Data!$F$3:$F$273),"") -> Hydrogen | G15: =IFERROR(_xlfn.XLOOKUP($B15,Raw_Data!$A$3:$A$273,Raw_Data!$J$3:$J$273),"") -> 45853 | H15: Series B | I15: =IFERROR(_xlfn.XLOOKUP($B15,Raw_Data!$A$3:$A$273,Raw_Data!$I$3:$I$273),"") -> 314.16 | J15: =IFERROR(_xlfn.XLOOKUP($B15,Raw_Data!$A$3:$A$273,Raw_Data!$L$3:$L$273),"") -> 95 | K15: =IFERROR(_xlfn.XLOOKUP($B15,Raw_Data!$A$3:$A$273,Raw_Data!$M$3:$M$273),"") -> 700 | L15: =IFERROR(_xlfn.XLOOKUP($B15,Raw_Data!$A$3:$A$273,Raw_Data!$Q$3:$Q$273),"") -> 0.47473684 | M15: =IFERROR(_xlfn.XLOOKUP($B15,Raw_Data!$A$3:$A$273,Raw_Data!$R$3:$R$273),"") -> AFW Partners; AP Ventures; Aramco Ventures; BHP Ventures; KDB Investment; SV Investment; MOL PLUS; Yanmar Holdings; Samsung Heavy Industries; BHP Ventures; MOL Switch; JB Investment (Private Equity); GS Engineering & Construction; Xplor Investment; GS Futures; Marunouchi Innovation Partners; Pathway Capital Management; Seoul Investment Partners; AFW Partners; AP Ventures; Odyssey Ventures (London); BonAngels Venture Partners; Quantum Ventures Korea; Kibo Invest; Temasek Holdings; Hanwha Investment & Securities Company; Gorilla Private Equity | N15: {=IF(M15="",0,COUNTA(_xlfn._xlws.FILTER(_xlfn.TEXTSPLIT(M15,";"), _xlfn.TEXTSPLIT(M15,";")<>"")))} -> 27 | O15: =IF(P15>0,"Y","N") -> Y | P15: =IFERROR(_xlfn.XLOOKUP($B15,Raw_Data!$A$3:$A$273,Raw_Data!$V$3:$V$273),"") -> 0.14814815 | Q15: =IF(R15>0,"Y","N") -> Y | R15: =IFERROR(_xlfn.XLOOKUP($B15,Raw_Data!$A$3:$A$273,Raw_Data!$Y$3:$Y$273),"") -> 0.85185185 | S15: {=_xlfn.LET(_xlpm.s, Raw_Data!W15,_xlpm.strat, _xlfn._xlws.FILTER(REF_Setup!$B$3:$B$40, REF_Setup!$B$3:$B$40<>""),IF(OR(_xlpm.s="",_xlpm.s=0),"Unclassified",IF(SUM(--ISNUMBER(SEARCH(_xlpm.strat, _xlpm.s)))>0, "Y", "N")) )} -> Y | T15: {=_xlfn.LET(_xlpm.s,M15,_xlpm.phil, _xlfn._xlws.FILTER(REF_Setup!$D$3:$D$5, REF_Setup!$D$3:$D$5<>""),IF(OR(_xlpm.s="", _xlpm.s=0),"Unclassified",IF(SUM(--ISNUMBER(SEARCH(_xlpm.phil, _xlpm.s)))>0, "Y", "N")))} -> N | U15: {=IF(M15="", "Unclassified", IF(AND(SUMPRODUCT(--ISNUMBER(SEARCH(REF_Setup!$B$3:$B$40,M15)))>0,SUMPRODUCT(--ISNUMBER(SEARCH(REF_Setup!$F$3:$F$15,M15)))>0),"Mixed",IF(SUMPRODUCT(--ISNUMBER(SEARCH(REF_Setup!$B$3:$B$40,M15)))>0,"Strategic Only",IF(SUMPRODUCT(--ISNUMBER(SEARCH(REF_Setup!$F$3:$F$15,M15)))>0,"VC Only","Unclassified"))))} -> Mixed
B16: =B15+1 -> 14 | C16: =IFERROR(_xlfn.XLOOKUP($B16,Raw_Data!$A$3:$A$273,Raw_Data!$B$3:$B$273),"") -> Ampcera | D16: =IFERROR(_xlfn.XLOOKUP($B16,Raw_Data!$A$3:$A$273,Raw_Data!$C$3:$C$273),"") -> San Jose, CA | E16: =IFERROR(_xlfn.XLOOKUP($B16,Raw_Data!$A$3:$A$273,Raw_Data!$D$3:$D$273),"") -> 2017 | F16: =IFERROR(_xlfn.XLOOKUP($B16,Raw_Data!$A$3:$A$273,Raw_Data!$F$3:$F$273),"") -> LDES | G16: =IFERROR(_xlfn.XLOOKUP($B16,Raw_Data!$A$3:$A$273,Raw_Data!$J$3:$J$273),"") -> 43220 | H16: Seed | I16: =IFERROR(_xlfn.XLOOKUP($B16,Raw_Data!$A$3:$A$273,Raw_Data!$I$3:$I$273),"") -> 1 | J16: =IFERROR(_xlfn.XLOOKUP($B16,Raw_Data!$A$3:$A$273,Raw_Data!$L$3:$L$273),"") -> 1 | K16: =IFERROR(_xlfn.XLOOKUP($B16,Raw_Data!$A$3:$A$273,Raw_Data!$M$3:$M$273),"") -> 10 | L16: =IFERROR(_xlfn.XLOOKUP($B16,Raw_Data!$A$3:$A$273,Raw_Data!$Q$3:$Q$273),"") -> 0 | N16: {=IF(M16="",0,COUNTA(_xlfn._xlws.FILTER(_xlfn.TEXTSPLIT(M16,";"), _xlfn.TEXTSPLIT(M16,";")<>"")))} -> 0 | O16: =IF(P16>0,"Y","N") -> Y | P16: =IFERROR(_xlfn.XLOOKUP($B16,Raw_Data!$A$3:$A$273,Raw_Data!$V$3:$V$273),"") -> N/A | Q16: =IF(R16>0,"Y","N") -> Y | R16: =IFERROR(_xlfn.XLOOKUP($B16,Raw_Data!$A$3:$A$273,Raw_Data!$Y$3:$Y$273),"") -> N/A | S16: {=_xlfn.LET(_xlpm.s, Raw_Data!W16,_xlpm.strat, _xlfn._xlws.FILTER(REF_Setup!$B$3:$B$40, REF_Setup!$B$3:$B$40<>""),IF(OR(_xlpm.s="",_xlpm.s=0),"Unclassified",IF(SUM(--ISNUMBER(SEARCH(_xlpm.strat, _xlpm.s)))>0, "Y", "N")) )} -> Unclassified | T16: {=_xlfn.LET(_xlpm.s,M16,_xlpm.phil, _xlfn._xlws.FILTER(REF_Setup!$D$3:$D$5, REF_Setup!$D$3:$D$5<>""),IF(OR(_xlpm.s="", _xlpm.s=0),"Unclassified",IF(SUM(--ISNUMBER(SEARCH(_xlpm.phil, _xlpm.s)))>0, "Y", "N")))} -> Unclassified | U16: {=IF(M16="", "Unclassified", IF(AND(SUMPRODUCT(--ISNUMBER(SEARCH(REF_Setup!$B$3:$B$40,M16)))>0,SUMPRODUCT(--ISNUMBER(SEARCH(REF_Setup!$F$3:$F$15,M16)))>0),"Mixed",IF(SUMPRODUCT(--ISNUMBER(SEARCH(REF_Setup!$B$3:$B$40,M16)))>0,"Strategic Only",IF(SUMPRODUCT(--ISNUMBER(SEARCH(REF_Setup!$F$3:$F$15,M16)))>0,"VC Only","Unclassified"))))} -> Unclassified
B17: =B16+1 -> 15 | C17: =IFERROR(_xlfn.XLOOKUP($B17,Raw_Data!$A$3:$A$273,Raw_Data!$B$3:$B$273),"") -> Anesi | D17: =IFERROR(_xlfn.XLOOKUP($B17,Raw_Data!$A$3:$A$273,Raw_Data!$C$3:$C$273),"") -> TN | E17: =IFERROR(_xlfn.XLOOKUP($B17,Raw_Data!$A$3:$A$273,Raw_Data!$D$3:$D$273),"") -> 2010 | F17: =IFERROR(_xlfn.XLOOKUP($B17,Raw_Data!$A$3:$A$273,Raw_Data!$F$3:$F$273),"") -> Buildings | G17: =IFERROR(_xlfn.XLOOKUP($B17,Raw_Data!$A$3:$A$273,Raw_Data!$J$3:$J$273),"") -> 44358 | H17: Series A | I17: =IFERROR(_xlfn.XLOOKUP($B17,Raw_Data!$A$3:$A$273,Raw_Data!$I$3:$I$273),"") -> 3.3 | J17: =IFERROR(_xlfn.XLOOKUP($B17,Raw_Data!$A$3:$A$273,Raw_Data!$L$3:$L$273),"") -> 3.3 | K17: =IFERROR(_xlfn.XLOOKUP($B17,Raw_Data!$A$3:$A$273,Raw_Data!$M$3:$M$273),"") -> 10 | L17: =IFERROR(_xlfn.XLOOKUP($B17,Raw_Data!$A$3:$A$273,Raw_Data!$Q$3:$Q$273),"") -> 0.24242424 | M17: =IFERROR(_xlfn.XLOOKUP($B17,Raw_Data!$A$3:$A$273,Raw_Data!$R$3:$R$273),"") -> Enbridge | N17: {=IF(M17="",0,COUNTA(_xlfn._xlws.FILTER(_xlfn.TEXTSPLIT(M17,";"), _xlfn.TEXTSPLIT(M17,";")<>"")))} -> 1 | O17: =IF(P17>0,"Y","N") -> N | P17: =IFERROR(_xlfn.XLOOKUP($B17,Raw_Data!$A$3:$A$273,Raw_Data!$V$3:$V$273),"") -> 0 | Q17: =IF(R17>0,"Y","N") -> Y | R17: =IFERROR(_xlfn.XLOOKUP($B17,Raw_Data!$A$3:$A$273,Raw_Data!$Y$3:$Y$273),"") -> 1 | S17: {=_xlfn.LET(_xlpm.s, Raw_Data!W17,_xlpm.strat, _xlfn._xlws.FILTER(REF_Setup!$B$3:$B$40, REF_Setup!$B$3:$B$40<>""),IF(OR(_xlpm.s="",_xlpm.s=0),"Unclassified",IF(SUM(--ISNUMBER(SEARCH(_xlpm.strat, _xlpm.s)))>0, "Y", "N")) )} -> N | T17: {=_xlfn.LET(_xlpm.s,M17,_xlpm.phil, _xlfn._xlws.FILTER(REF_Setup!$D$3:$D$5, REF_Setup!$D$3:$D$5<>""),IF(OR(_xlpm.s="", _xlpm.s=0),"Unclassified",IF(SUM(--ISNUMBER(SEARCH(_xlpm.phil, _xlpm.s)))>0, "Y", "N")))} -> N | U17: {=IF(M17="", "Unclassified", IF(AND(SUMPRODUCT(--ISNUMBER(SEARCH(REF_Setup!$B$3:$B$40,M17)))>0,SUMPRODUCT(--ISNUMBER(SEARCH(REF_Setup!$F$3:$F$15,M17)))>0),"Mixed",IF(SUMPRODUCT(--ISNUMBER(SEARCH(REF_Setup!$B$3:$B$40,M17)))>0,"Strategic Only",IF(SUMPRODUCT(--ISNUMBER(SEARCH(REF_Setup!$F$3:$F$15,M17)))>0,"VC Only","Unclassified"))))} -> Unclassified
B18: =B17+1 -> 16 | C18: =IFERROR(_xlfn.XLOOKUP($B18,Raw_Data!$A$3:$A$273,Raw_Data!$B$3:$B$273),"") -> Anesi | D18: =IFERROR(_xlfn.XLOOKUP($B18,Raw_Data!$A$3:$A$273,Raw_Data!$C$3:$C$273),"") -> TN | E18: =IFERROR(_xlfn.XLOOKUP($B18,Raw_Data!$A$3:$A$273,Raw_Data!$D$3:$D$273),"") -> 2010 | F18: =IFERROR(_xlfn.XLOOKUP($B18,Raw_Data!$A$3:$A$273,Raw_Data!$F$3:$F$273),"") -> Buildings | G18: =IFERROR(_xlfn.XLOOKUP($B18,Raw_Data!$A$3:$A$273,Raw_Data!$J$3:$J$273),"") -> 44869 | H18: Series A | I18: =IFERROR(_xlfn.XLOOKUP($B18,Raw_Data!$A$3:$A$273,Raw_Data!$I$3:$I$273),"") -> 20.8 | J18: =IFERROR(_xlfn.XLOOKUP($B18,Raw_Data!$A$3:$A$273,Raw_Data!$L$3:$L$273),"") -> 17.5 | K18: =IFERROR(_xlfn.XLOOKUP($B18,Raw_Data!$A$3:$A$273,Raw_Data!$M$3:$M$273),"") -> 36.5 | L18: =IFERROR(_xlfn.XLOOKUP($B18,Raw_Data!$A$3:$A$273,Raw_Data!$Q$3:$Q$273),"") -> 0 | M18: =IFERROR(_xlfn.XLOOKUP($B18,Raw_Data!$A$3:$A$273,Raw_Data!$R$3:$R$273),"") -> Energy Impact Partners | N18: {=IF(M18="",0,COUNTA(_xlfn._xlws.FILTER(_xlfn.TEXTSPLIT(M18,";"), _xlfn.TEXTSPLIT(M18,";")<>"")))} -> 1 | O18: =IF(P18>0,"Y","N") -> N | P18: =IFERROR(_xlfn.XLOOKUP($B18,Raw_Data!$A$3:$A$273,Raw_Data!$V$3:$V$273),"") -> 0 | Q18: =IF(R18>0,"Y","N") -> Y | R18: =IFERROR(_xlfn.XLOOKUP($B18,Raw_Data!$A$3:$A$273,Raw_Data!$Y$3:$Y$273),"") -> 1 | S18: {=_xlfn.LET(_xlpm.s, Raw_Data!W18,_xlpm.strat, _xlfn._xlws.FILTER(REF_Setup!$B$3:$B$40, REF_Setup!$B$3:$B$40<>""),IF(OR(_xlpm.s="",_xlpm.s=0),"Unclassified",IF(SUM(--ISNUMBER(SEARCH(_xlpm.strat, _xlpm.s)))>0, "Y", "N")) )} -> N | T18: {=_xlfn.LET(_xlpm.s,M18,_xlpm.phil, _xlfn._xlws.FILTER(REF_Setup!$D$3:$D$5, REF_Setup!$D$3:$D$5<>""),IF(OR(_xlpm.s="", _xlpm.s=0),"Unclassified",IF(SUM(--ISNUMBER(SEARCH(_xlpm.phil, _xlpm.s)))>0, "Y", "N")))} -> N | U18: {=IF(M18="", "Unclassified", IF(AND(SUMPRODUCT(--ISNUMBER(SEARCH(REF_Setup!$B$3:$B$40,M18)))>0,SUMPRODUCT(--ISNUMBER(SEARCH(REF_Setup!$F$3:$F$15,M18)))>0),"Mixed",IF(SUMPRODUCT(--ISNUMBER(SEARCH(REF_Setup!$B$3:$B$40,M18)))>0,"Strategic Only",IF(SUMPRODUCT(--ISNUMBER(SEARCH(REF_Setup!$F$3:$F$15,M18)))>0,"VC Only","Unclassified"))))} -> VC Only
